Workbook

Sheet Saving monthly Oct-2022
A1: ក្រុម​សន្សំ​ប្រាក់ «សន្សំSANSAM»
A2: ការសន្សំ​ចាប់​ពី​៥ដុល្លារ​ឡើង​ទៅក្នុង​មួយខែ ដោយ​សមាជិក​នឹង​ទទួល​បានការប្រាក់ប្រចាំ​ខែ0.83%
A3: ចំពោះ​សមាជិក​ដែលដាក់ប្រាក់​កម្ចី​គឺក្នុងអត្រា​ការប្រាក់​១០%ក្នុង​មួយឆ្នាំ​សម្រាប់ក្រុម​ប្រឹក្សាភិបាល​ ១៤.៤%ក្នុង​មួយឆ្នាំសម្រាប់​សមាជិកស្នូល ១៨%ក្នុងមួយឆ្នាំ​សម្រាប់​សមាជិក​ធម្មតា ៣%​ក្នុងមួយឆ្នាំ​សម្រាប់​សមាជិក​បញ្ញើ
A4: ការ​ដាក់​ប្រាក់​សន្សំចាប់ពី​ថ្ងៃទី១ដល់ថ្ងៃទី១០រៀងរាល់ខែ
A5: ពេលវេលាទទួល​បាន​កម្ចី​ចន្លោះពីថ្ងៃទី១០ដល់ថ្ងៃទី១៥​រៀងរាល់ខែ
A6: តារាងសន្សំ​ខែ តុលា ឆ្នាំ២០២២
A7: ល.រ | B7: ឈ្មោះ​សមាជិកដាក់សន្សំ​ | C7: ភេទ | D7: តួនាទី​ក្នុង​សន្សំ | E7: ថ្ងៃខែដាក់សន្សំ | F7: ប្រាក់ដាក់សន្សំ | G7: ការប្រាក់ទទួលបាន | H7: សមតុល្យ​សាច់ប្រាក់ | I7: ប្រាក់បានដក | J7: សមតុល្យ​សាច់ប្រាក់ក្រោយដក
A8: 1 | B8: អាត់ ធន់ | C8: ប្រុស | D8: ស្ថាបនិក | E8: 44844 | F8: 3500 | H8: =F8+G8 -> 3500 | J8: =G8+H8-I8 -> 3500
A9: 2 | B9: ប៉ិច ពិសី | C9: ប្រុស | D9: ស្ថាបនិក | E9: 44844 | F9: 5000 | H9: =F9+G9 -> 5000 | J9: =G9+H9-I9 -> 5000
A10: 3 | B10: ហុង រស្មី | C10: ប្រុស | D10: ស្ថាបនិក | E10: 44844 | F10: 5000 | H10: =F10+G10 -> 5000 | J10: =G10+H10-I10 -> 5000
A11: 4 | B11: ស៊ិន ពុទ្ធារី | C11: ស្រី | D11: ស្ថាបនិក | E11: 44844 | F11: 5000 | H11: =F11+G11 -> 5000 | J11: =G11+H11-I11 -> 5000
A12: 5 | B12: វន់ ពៅ | C12: ប្រុស | D12: ស្ថាបនិក | E12: 44844 | F12: 100 | H12: =F12+G12 -> 100 | J12: =G12+H12-I12 -> 100
A13: 6 | B13: ស ម៉ូរ៉ា | C13: ប្រុស | D13: ស្ថាបនិក | E13: 44844 | F13: 2000 | H13: =F13+G13 -> 2000 | J13: =G13+H13-I13 -> 2000
A14: 7 | B14: ណុប វី | C14: ប្រុស | D14: ស្ថាបនិក | E14: 44844 | F14: 5000 | H14: =F14+G14 -> 5000 | J14: =G14+H14-I14 -> 5000
A15: 8 | B15: អ៊ូ រិទ្ធី | C15: ប្រុស | D15: ស្ថាបនិក | E15: 44844 | F15: 4000 | H15: =F15+G15 -> 4000 | J15: =G15+H15-I15 -> 4000
F16: =SUM(F8:F15) -> 29600 | G16: =SUM(G8:G15) -> 0 | H16: =SUM(H8:H15) -> 29600 | I16: 0 | J16: =SUM(J8:J15) -> 29600

Sheet Saving monthly November-22
A1: ក្រុម​សន្សំ​ប្រាក់ «សន្សំSANSAM»
A2: ការសន្សំ​ចាប់​ពី​៥ដុល្លារ​ឡើង​ទៅក្នុង​មួយខែ ដោយ​សមាជិក​នឹង​ទទួល​បានការប្រាក់ប្រចាំ​ខែ0.83%
A3: ចំពោះ​សមាជិក​ដែលដាក់ប្រាក់​កម្ចី​គឺក្នុងអត្រា​ការប្រាក់​១០%ក្នុង​មួយឆ្នាំ​សម្រាប់ក្រុម​ប្រឹក្សាភិបាល​ ១៤.៤%ក្នុង​មួយឆ្នាំសម្រាប់​សមាជិកស្នូល ១៨%ក្នុងមួយឆ្នាំ​សម្រាប់​សមាជិក​ធម្មតា ៣%​ក្នុងមួយឆ្នាំ​សម្រាប់​សមាជិក​បញ្ញើ
A4: ការ​ដាក់​ប្រាក់​សន្សំចាប់ពី​ថ្ងៃទី១ដល់ថ្ងៃទី១០រៀងរាល់ខែ
A5: ពេលវេលាទទួល​បាន​កម្ចី​ចន្លោះពីថ្ងៃទី១០ដល់ថ្ងៃទី១៥​រៀងរាល់ខែ
A6: តារាងសន្សំ​ខែ វិច្ឆិកា ឆ្នាំ២០២២
A7: ល.រ | B7: ឈ្មោះ​សមាជិកដាក់សន្សំ​ | C7: ភេទ | D7: តួនាទី​ក្នុង​សន្សំ | E7: ថ្ងៃខែដាក់សន្សំ | F7: ប្រាក់ដើម | G7: ប្រាក់ដាក់សន្សំ | H7: ការប្រាក់ទទួលបាន | I7: សមតុល្យ​សាច់ប្រាក់ | J7: ប្រាក់បានដក | K7: សមតុល្យ​សាច់ប្រាក់ក្រោយដក
A8: 1 | B8: អាត់ ធន់ | C8: ប្រុស | D8: ស្ថាបនិក | E8: 44844 | F8: 3500 | H8: =F8*0.83% -> 29.05 | I8: =F8+G8+H8 -> 3529.05 | K8: =I8-J8 -> 3529.05
A9: 2 | B9: ប៉ិច ពិសី | C9: ប្រុស | D9: ស្ថាបនិក | E9: 44844 | F9: 5000 | G9: 500 | H9: =F9*0.83% -> 41.5 | I9: =F9+G9+H9 -> 5541.5 | K9: =I9-J9 -> 5541.5
A10: 3 | B10: ហុង រស្មី | C10: ប្រុស | D10: ស្ថាបនិក | E10: 44844 | F10: 5000 | G10: 100 | H10: =F10*0.83% -> 41.5 | I10: =F10+G10+H10 -> 5141.5 | K10: =I10-J10 -> 5141.5
A11: 4 | B11: ស៊ិន ពុទ្ធារី | C11: ស្រី | D11: ស្ថាបនិក | E11: 44844 | F11: 5000 | G11: 100 | H11: =F11*0.83% -> 41.5 | I11: =F11+G11+H11 -> 5141.5 | K11: =I11-J11 -> 5141.5
A12: 5 | B12: វន់ ពៅ | C12: ប្រុស | D12: ស្ថាបនិក | E12: 44844 | F12: 100 | H12: =F12*0.83% -> 0.83 | I12: =F12+G12+H12 -> 100.83 | K12: =I12-J12 -> 100.83
A13: 6 | B13: ស ម៉ូរ៉ា | C13: ប្រុស | D13: ស្ថាបនិក | E13: 44844 | F13: 2000 | G13: 50.17 | H13: =F13*0.83% -> 16.6 | I13: =F13+G13+H13 -> 2066.77 | K13: =I13-J13 -> 2066.77
A14: 7 | B14: ណុប វី | C14: ប្រុស | D14: ស្ថាបនិក | E14: 44844 | F14: 5000 | G14: 50.8 | H14: =F14*0.83% -> 41.5 | I14: =F14+G14+H14 -> 5092.3 | K14: =I14-J14 -> 5092.3
A15: 8 | B15: អ៊ូ រិទ្ធី | C15: ប្រុស | D15: ស្ថាបនិក | E15: 44844 | F15: 4000 | G15: 100 | H15: =F15*0.83% -> 33.2 | I15: =F15+G15+H15 -> 4133.2 | K15: =I15-J15 -> 4133.2
A16: 9 | B16: សំ​ សុម៉ុនី | C16: ប្រុស | D16: សមាជិក | E16: 44874 | F16: 50 | I16: =F16+G16+H16 -> 50 | K16: =I16-J16 -> 50
F17: =SUM(F8:F16) -> 29650 | G17: =SUM(G8:G16) -> 900.97 | H17: =SUM(H8:H16) -> 245.68 | I17: =SUM(I8:I16) -> 30796.65 | J17: 0 | K17: =SUM(K8:K16) -> 30796.65

Sheet Saving monthly December-22
A1: ក្រុម​សន្សំ​ប្រាក់ «សន្សំSANSAM»
A2: ការសន្សំ​ចាប់​ពី​៥ដុល្លារ​ឡើង​ទៅក្នុង​មួយខែ ដោយ​សមាជិក​នឹង​ទទួល​បានការប្រាក់ប្រចាំ​ខែ0.83%
A3: ចំពោះ​សមាជិក​ដែលដាក់ប្រាក់​កម្ចី​គឺក្នុងអត្រា​ការប្រាក់​១០%ក្នុង​មួយឆ្នាំ​សម្រាប់ក្រុម​ប្រឹក្សាភិបាល​ ១៤.៤%ក្នុង​មួយឆ្នាំសម្រាប់​សមាជិកស្នូល ១៨%ក្នុងមួយឆ្នាំ​សម្រាប់​សមាជិក​ធម្មតា ៣%​ក្នុងមួយឆ្នាំ​សម្រាប់​សមាជិក​បញ្ញើ
A4: ការ​ដាក់​ប្រាក់​សន្សំចាប់ពី​ថ្ងៃទី១ដល់ថ្ងៃទី១០រៀងរាល់ខែ
A5: ពេលវេលាទទួល​បាន​កម្ចី​ចន្លោះពីថ្ងៃទី១០ដល់ថ្ងៃទី១៥​រៀងរាល់ខែ
A6: តារាងសន្សំ​ខែ ធ្នូ ឆ្នាំ២០២២
A7: ល.រ | B7: ឈ្មោះ​សមាជិកដាក់សន្សំ​ | C7: ភេទ | D7: តួនាទី​ក្នុង​សន្សំ | E7: ថ្ងៃខែដាក់សន្សំ | F7: ប្រាក់ដើម | G7: ប្រាក់ដាក់សន្សំ | H7: ការប្រាក់ទទួលបាន | I7: សមតុល្យ​សាច់ប្រាក់ | J7: ប្រាក់បានដក | K7: សមតុល្យ​សាច់ប្រាក់ក្រោយដក
A8: 1 | B8: អាត់ ធន់ | C8: ប្រុស | D8: ស្ថាបនិក | E8: 44844 | F8: ='Saving monthly November-22'!K8 -> 3529.05 | G8: 0.07 | H8: =F8*0.83% -> 29.291115 | I8: =F8+G8+H8 -> 3558.4111 | K8: =I8-J8 -> 3558.4111
A9: 2 | B9: ប៉ិច ពិសី | C9: ប្រុស | D9: ស្ថាបនិក | E9: 44844 | F9: ='Saving monthly November-22'!K9 -> 5541.5 | H9: =F9*0.83% -> 45.99445 | I9: =F9+G9+H9 -> 5587.4945 | K9: =I9-J9 -> 5587.4945
A10: 3 | B10: ហុង រស្មី | C10: ប្រុស | D10: ស្ថាបនិក | E10: 44905 | F10: ='Saving monthly November-22'!K10 -> 5141.5 | G10: 100 | H10: =F10*0.83% -> 42.67445 | I10: =F10+G10+H10 -> 5284.1745 | K10: =I10-J10 -> 5284.1745
A11: 4 | B11: ស៊ិន ពុទ្ធារី | C11: ស្រី | D11: ស្ថាបនិក | E11: 44844 | F11: ='Saving monthly November-22'!K11 -> 5141.5 | H11: =F11*0.83% -> 42.67445 | I11: =F11+G11+H11 -> 5184.1745 | K11: =I11-J11 -> 5184.1745
A12: 5 | B12: វន់ ពៅ | C12: ប្រុស | D12: ស្ថាបនិក | E12: 44844 | F12: ='Saving monthly November-22'!K12 -> 100.83 | G12: 100 | H12: =F12*0.83% -> 0.836889 | I12: =F12+G12+H12 -> 201.66689 | K12: =I12-J12 -> 201.66689
A13: 6 | B13: ស ម៉ូរ៉ា | C13: ប្រុស | D13: ស្ថាបនិក | E13: 44844 | F13: ='Saving monthly November-22'!K13 -> 2066.77 | G13: 31.9 | H13: =F13*0.83% -> 17.154191 | I13: =F13+G13+H13 -> 2115.8242 | K13: =I13-J13 -> 2115.8242
A14: 7 | B14: ណុប វី | C14: ប្រុស | D14: ស្ថាបនិក | E14: 44844 | F14: 5092.3 | G14: 54.12 | H14: =F14*0.83% -> 42.26609 | I14: =F14+G14+H14 -> 5188.6861 | K14: =I14-J14 -> 5188.6861
A15: 8 | B15: អ៊ូ រិទ្ធី | C15: ប្រុស | D15: ស្ថាបនិក | E15: 44844 | F15: ='Saving monthly November-22'!K15 -> 4133.2 | G15: 200 | H15: =F15*0.83% -> 34.30556 | I15: =F15+G15+H15 -> 4367.5056 | K15: =I15-J15 -> 4367.5056
A16: 9 | B16: សំ​ សុម៉ុនី | C16: ប្រុស | D16: សមាជិក | E16: 44874 | F16: 50 | G16: 50 | H16: =F16*0.83% -> 0.415 | I16: =F16+G16+H16 -> 100.415 | K16: =I16-J16 -> 100.415
F17: =SUM(F8:F16) -> 30796.65 | G17: =SUM(G8:G16) -> 536.09 | H17: =SUM(H8:H16) -> 255.6122 | I17: =SUM(I8:I16) -> 31588.352 | J17: 0 | K17: =SUM(K8:K16) -> 31588.352

Sheet Saving monthly Jan-23
A1: ក្រុម​សន្សំ​ប្រាក់ «សន្សំSANSAM»
A2: ការសន្សំ​ចាប់​ពី​៥ដុល្លារ​ឡើង​ទៅក្នុង​មួយខែ ដោយ​សមាជិក​នឹង​ទទួល​បានការប្រាក់ប្រចាំ​ខែ0.83%
A3: ចំពោះ​សមាជិក​ដែលដាក់ប្រាក់​កម្ចី​គឺក្នុងអត្រា​ការប្រាក់​១០%ក្នុង​មួយឆ្នាំ​សម្រាប់ក្រុម​ប្រឹក្សាភិបាល​ ១៤.៤%ក្នុង​មួយឆ្នាំសម្រាប់​សមាជិកស្នូល ១៨%ក្នុងមួយឆ្នាំ​សម្រាប់​សមាជិក​ធម្មតា ៣%​ក្នុងមួយឆ្នាំ​សម្រាប់​សមាជិក​បញ្ញើ
A4: ការ​ដាក់​ប្រាក់​សន្សំចាប់ពី​ថ្ងៃទី១ដល់ថ្ងៃទី១០រៀងរាល់ខែ
A5: ពេលវេលាទទួល​បាន​កម្ចី​ចន្លោះពីថ្ងៃទី១០ដល់ថ្ងៃទី១៥​រៀងរាល់ខែ
A6: តារាងសន្សំ​ខែ មករា​ ឆ្នាំ២០២៣
A7: ល.រ | B7: ឈ្មោះ​សមាជិកដាក់សន្សំ​ | C7: ភេទ | D7: តួនាទី​ក្នុង​សន្សំ | E7: ថ្ងៃខែដាក់សន្សំ | F7: ប្រាក់ដើម | G7: ប្រាក់ដាក់សន្សំ | H7: ការប្រាក់ទទួលបាន | I7: សមតុល្យ​សាច់ប្រាក់ | J7: ប្រាក់បានដក | K7: សមតុល្យ​សាច់ប្រាក់ក្រោយដក
A8: 1 | B8: អាត់ ធន់ | C8: ប្រុស | D8: ស្ថាបនិក | E8: 44928 | F8: 3558.4111 | G8: 44.81 | H8: =F8*0.83% -> 29.534812 | I8: =F8+G8+H8 -> 3632.7559 | K8: =I8-J8 -> 3632.7559
A9: 2 | B9: PECH PISEY | C9: ប្រុស | D9: ស្ថាបនិក | E9: 44936 | F9: 5587.4945 | G9: 100 | H9: =F9*0.83% -> 46.376204 | I9: =F9+G9+H9 -> 5733.8707 | K9: =I9-J9 -> 5733.8707
A10: 3 | B10: HONG REAKSMEY | C10: ប្រុស | D10: ស្ថាបនិក | E10: 44937 | F10: 5284.1745 | G10: 100 | H10: =F10*0.83% -> 43.858648 | I10: =F10+G10+H10 -> 5428.0331 | K10: =I10-J10 -> 5428.0331
A11: 4 | B11: SIN PUTHEARY | C11: ស្រី | D11: ស្ថាបនិក | E11: 44844 | F11: 5184.1745 | H11: =F11*0.83% -> 43.028648 | I11: =F11+G11+H11 -> 5227.2031 | K11: =I11-J11 -> 5227.2031
A12: 5 | B12: PAO VORN | C12: ប្រុស | D12: ស្ថាបនិក | E12: 44844 | F12: 201.66689 | H12: =F12*0.83% -> 1.6738352 | I12: =F12+G12+H12 -> 203.34072 | K12: =I12-J12 -> 203.34072
A13: 6 | B13: SAR MORA | C13: ប្រុស | D13: ស្ថាបនិក | E13: 44936 | F13: 2115.8242 | G13: 33.63 | H13: =F13*0.83% -> 17.561341 | I13: =F13+G13+H13 -> 2167.0155 | K13: =I13-J13 -> 2167.0155
A14: 7 | B14: NOP VY | C14: ប្រុស | D14: ស្ថាបនិក | E14: 44936 | F14: 5188.6861 | G14: 57.44 | H14: =F14*0.83% -> 43.066095 | I14: =F14+G14+H14 -> 5289.1922 | K14: =I14-J14 -> 5289.1922
A15: 8 | B15: OU RITHY | C15: ប្រុស | D15: ស្ថាបនិក | E15: 44935 | F15: 4367.5056 | G15: 223 | H15: =F15*0.83% -> 36.250296 | I15: =F15+G15+H15 -> 4626.7559 | K15: =I15-J15 -> 4626.7559
A16: 9 | B16: SAM SOMONY | C16: ប្រុស | D16: សមាជិក | E16: 44936 | F16: 100.415 | G16: 50 | H16: =F16*0.83% -> 0.8334445 | I16: =F16+G16+H16 -> 151.24844 | K16: =I16-J16 -> 151.24844
A17: 10 | B17: KOY MAQUIS | C17: ប្រុស | D17: សមាជិក | E17: 44941 | F17: 5 | I17: =F17+G17+H17 -> 5 | K17: =I17-J17 -> 5
A18: 11 | B18: Ly Malin | C18: ស្រី | D18: សមាជិក | E18: 44950 | F18: 20 | I18: =F18+G18+H18 -> 20 | K18: =I18-J18 -> 20
A19: 12 | B19: Van Bunna | D19: សមាជិក | E19: 44951 | F19: 10 | I19: =F19+G19+H19 -> 10 | K19: =I19-J19 -> 10
A20: 13 | B20: Long Borin | C20: ស្រី | D20: សមាជិក | E20: 44957 | F20: 15 | I20: =F20+G20+H20 -> 15 | K20: =I20-J20 -> 15
F22: =SUM(F8:F20) -> 31638.352 | G22: =SUM(G8:G17) -> 608.88 | H22: =SUM(H8:H17) -> 262.18332 | I22: =SUM(I8:I20) -> 32509.416 | J22: =SUM(J8:J17) -> 0 | K22: =SUM(K8:K20) -> 32509.416

Sheet Saving monthly Feb-23
A1: ក្រុម​សន្សំ​ប្រាក់ «សន្សំSANSAM»
A2: ការសន្សំ​ចាប់​ពី​៥ដុល្លារ​ឡើង​ទៅក្នុង​មួយខែ ដោយ​សមាជិក​នឹង​ទទួល​បានការប្រាក់ប្រចាំ​ខែ0.83%
A3: ចំពោះ​សមាជិក​ដែលដាក់ប្រាក់​កម្ចី​គឺក្នុងអត្រា​ការប្រាក់​១០%ក្នុង​មួយឆ្នាំ​សម្រាប់ក្រុម​ប្រឹក្សាភិបាល​ ១៤.៤%ក្នុង​មួយឆ្នាំសម្រាប់​សមាជិកស្នូល ១៨%ក្នុងមួយឆ្នាំ​សម្រាប់​សមាជិក​ធម្មតា ៣%​ក្នុងមួយឆ្នាំ​សម្រាប់​សមាជិក​បញ្ញើ
A4: ការ​ដាក់​ប្រាក់​សន្សំចាប់ពី​ថ្ងៃទី១ដល់ថ្ងៃទី១០រៀងរាល់ខែ
A5: ពេលវេលាទទួល​បាន​កម្ចី​ចន្លោះពីថ្ងៃទី១០ដល់ថ្ងៃទី១៥​រៀងរាល់ខែ
A6: តារាងសន្សំ​ខែ កុម្ភះ​ ឆ្នាំ២០២៣
A7: ល.រ | B7: ឈ្មោះ​សមាជិកដាក់សន្សំ​ | C7: ភេទ | D7: តួនាទី​ក្នុង​សន្សំ | E7: ថ្ងៃខែដាក់សន្សំ | F7: ប្រាក់ដើម | G7: ប្រាក់ដាក់សន្សំ | H7: ការប្រាក់ទទួលបាន | I7: សមតុល្យ​សាច់ប្រាក់ | J7: ប្រាក់បានដក | K7: សមតុល្យ​សាច់ប្រាក់ក្រោយដក
A8: 1 | B8: ART THORN | C8: ប្រុស | D8: ស្ថាបនិក | E8: 44972 | F8: 3632.7559 | G8: 30.54 | H8: =F8*0.83% -> 30.151874 | I8: =F8+G8+H8 -> 3693.4478 | K8: =I8-J8 -> 3693.4478
A9: 2 | B9: ប៉ិច ពិសី | C9: ប្រុស | D9: ស្ថាបនិក | E9: 44844 | F9: 5733.8707 | H9: =F9*0.83% -> 47.591126 | I9: =F9+G9+H9 -> 5781.4618 | K9: =I9-J9 -> 5781.4618
A10: 3 | B10: HONG REAKSMEY | C10: ប្រុស | D10: ស្ថាបនិក | E10: 44971 | F10: 5428.0331 | G10: 50 | H10: =F10*0.83% -> 45.052675 | I10: =F10+G10+H10 -> 5523.0858 | K10: =I10-J10 -> 5523.0858
A11: 4 | B11: ស៊ិន ពុទ្ធារី | C11: ស្រី | D11: ស្ថាបនិក | E11: 44844 | F11: 5227.2031 | H11: =F11*0.83% -> 43.385786 | I11: =F11+G11+H11 -> 5270.5889 | K11: =I11-J11 -> 5270.5889
A12: 5 | B12: PAO VORN | C12: ប្រុស | D12: ស្ថាបនិក | E12: 44964 | F12: 203.34072 | G12: 50 | H12: =F12*0.83% -> 1.687728 | I12: =F12+G12+H12 -> 255.02845 | K12: =I12-J12 -> 255.02845
A13: 6 | B13: SOR MORA | C13: ប្រុស | D13: ស្ថាបនិក | E13: 44967 | F13: 2167.0155 | G13: 5.36 | H13: =F13*0.83% -> 17.986229 | I13: =F13+G13+H13 -> 2190.3618 | K13: =I13-J13 -> 2190.3618
A14: 7 | B14: ណុប វី | C14: ប្រុស | D14: ស្ថាបនិក | E14: 44968 | F14: 5289.1922 | G14: 60.76 | H14: =F14*0.83% -> 43.900295 | I14: =F14+G14+H14 -> 5393.8525 | K14: =I14-J14 -> 5393.8525
A15: 8 | B15: OU RITHTY | C15: ប្រុស | D15: ស្ថាបនិក | E15: 44967 | F15: 4626.7559 | G15: 100 | H15: =F15*0.83% -> 38.402074 | I15: =F15+G15+H15 -> 4765.1579 | K15: =I15-J15 -> 4765.1579
A16: 9 | B16: SENG RITHY | C16: ប្រុស | D16: សមាជិក | E16: 44958 | F16: 5 | I16: =F16+G16+H16 -> 5 | K16: =I16-J16 -> 5
A17: 10 | B17: OU TEPPHALIN | C17: ស្រី | D17: សមាជិក | E17: 44958 | F17: 20 | I17: =F17+G17+H17 -> 20 | K17: =I17-J17 -> 20
A18: 11 | B18: YIM BUNTHENG | D18: សមាជិក | E18: 44958 | F18: 10 | I18: =F18+G18+H18 -> 10 | K18: =I18-J18 -> 10
A19: 12 | B19: THENG SAVOEUN | D19: សមាជិក | E19: 44967 | F19: 50 | I19: =F19+G19+H19 -> 50 | K19: =I19-J19 -> 50
A20: 13 | B20: OU VANN | D20: សមាជិក | E20: 44967 | F20: 20 | I20: =F20+G20+H20 -> 20 | K20: =I20-J20 -> 20
A21: 14 | B21: SIYONN SOTHEARITH | C21: ប្រុស | D21: សមាជិក | E21: 44970 | F21: 100 | I21: =F21+G21+H21 -> 100 | K21: =I21-J21 -> 100
A22: 15 | B22: YEAN REAKSMEY | D22: សមាជិក | E22: 44975 | F22: 10 | I22: =F22+G22+H22 -> 10 | K22: =I22-J22 -> 10
A23: 16 | B23: SON PENH | D23: សមាជិក | E23: 44978 | F23: 20 | I23: =F23+G23+H23 -> 20 | K23: =I23-J23 -> 20
A24: 17 | B24: សំ​ សុម៉ុនី | C24: ប្រុស | D24: សមាជិក | E24: 44964 | F24: 151.24844 | G24: 50 | H24: =F24*0.83% -> 1.2553621 | I24: =F24+G24+H24 -> 202.50381 | K24: =I24-J24 -> 202.50381
A25: 18 | B25: KOY MAQUIS | C25: ប្រុស | D25: សមាជិក | E25: 44971 | F25: 5 | G25: 10 | H25: =F25*0.83% -> 0.0415 | I25: =F25+G25+H25 -> 15.0415 | K25: =I25-J25 -> 15.0415
A26: 19 | B26: Ly Malin | C26: ស្រី | D26: សមាជិក | E26: 44967 | F26: 20 | G26: 20 | H26: =F26*0.83% -> 0.166 | I26: =F26+G26+H26 -> 40.166 | K26: =I26-J26 -> 40.166
A27: 20 | B27: Van Bunna | D27: សមាជិក | E27: 44951 | F27: 10 | I27: =F27+G27+H27 -> 10 | K27: =I27-J27 -> 10
A28: 21 | B28: Long Borin | C28: ស្រី | D28: សមាជិក | E28: 44957 | F28: 15 | H28: =F28*0.83% -> 0.1245 | I28: =F28+G28+H28 -> 15.1245 | K28: =I28-J28 -> 15.1245
F30: =SUM(F8:F28) -> 32744.416 | G30: =SUM(G8:G28) -> 376.66 | H30: =SUM(H8:H28) -> 269.74515 | I30: =SUM(I8:I28) -> 33390.821 | J30: =SUM(J8:J28) -> 0 | K30: =SUM(K8:K28) -> 33390.821

Sheet Saving monthly Mar-23
A1: ក្រុម​សន្សំ​ប្រាក់ «សន្សំSANSAM»
A2: ការសន្សំ​ចាប់​ពី​៥ដុល្លារ​ឡើង​ទៅក្នុង​មួយខែ ដោយ​សមាជិក​នឹង​ទទួល​បានការប្រាក់ប្រចាំ​ខែ0.83%
A3: ចំពោះ​សមាជិក​ដែលដាក់ប្រាក់​កម្ចី​គឺក្នុងអត្រា​ការប្រាក់​១០%ក្នុង​មួយឆ្នាំ​សម្រាប់ក្រុម​ប្រឹក្សាភិបាល​ ១៤.៤%ក្នុង​មួយឆ្នាំសម្រាប់​សមាជិកស្នូល ១៨%ក្នុងមួយឆ្នាំ​សម្រាប់​សមាជិក​ធម្មតា ៣%​ក្នុងមួយឆ្នាំ​សម្រាប់​សមាជិក​បញ្ញើ
A4: ការ​ដាក់​ប្រាក់​សន្សំចាប់ពី​ថ្ងៃទី១ដល់ថ្ងៃទី១០រៀងរាល់ខែ
A5: ពេលវេលាទទួល​បាន​កម្ចី​ចន្លោះពីថ្ងៃទី១០ដល់ថ្ងៃទី១៥​រៀងរាល់ខែ
A6: តារាងសន្សំ​ខែ មីនា ឆ្នាំ២០២៣
A7: ល.រ | B7: ឈ្មោះ​សមាជិកដាក់សន្សំ​ | C7: ភេទ | D7: តួនាទី​ក្នុង​សន្សំ | E7: ថ្ងៃខែដាក់សន្សំ | F7: ប្រាក់ដើម | G7: ប្រាក់ដាក់សន្សំ | H7: ការប្រាក់ទទួលបាន | I7: សមតុល្យ​សាច់ប្រាក់ | J7: ប្រាក់បានដក | K7: សមតុល្យ​សាច់ប្រាក់ក្រោយដក
A8: 1 | B8: ART THORN | C8: ប្រុស | D8: ស្ថាបនិក | E8: 44995 | F8: 3693.4478 | G8: 46.27 | H8: =F8*0.83% -> 30.655617 | I8: =F8+G8+H8 -> 3770.3734 | K8: =I8-J8 -> 3770.3734
A9: 2 | B9: PECH PISEY | C9: ប្រុស | D9: ស្ថាបនិក | E9: 44995 | F9: 5781.4618 | G9: 50 | H9: =F9*0.83% -> 47.986133 | I9: =F9+G9+H9 -> 5879.4479 | K9: =I9-J9 -> 5879.4479
A10: 3 | B10: HONG REAKSMEY | C10: ប្រុស | D10: ស្ថាបនិក | E10: 44995 | F10: 5523.0858 | G10: 50 | H10: =F10*0.83% -> 45.841612 | I10: =F10+G10+H10 -> 5618.9274 | K10: =I10-J10 -> 5618.9274
A11: 4 | B11: SIN PUTHEARY | C11: ស្រី | D11: ស្ថាបនិក | E11: 44844 | F11: 5270.5889 | H11: =F11*0.83% -> 43.745888 | I11: =F11+G11+H11 -> 5314.3348 | K11: =I11-J11 -> 5314.3348
A12: 5 | B12: PAO VORN | C12: ប្រុស | D12: ស្ថាបនិក | E12: 44964 | F12: 255.02845 | H12: =F12*0.83% -> 2.1167362 | I12: =F12+G12+H12 -> 257.14519 | K12: =I12-J12 -> 257.14519
A13: 6 | B13: SOR MORA | C13: ប្រុស | D13: ស្ថាបនិក | E13: 44967 | F13: 2190.3618 | G13: 7.09 | H13: =F13*0.83% -> 18.180003 | I13: =F13+G13+H13 -> 2215.6318 | K13: =I13-J13 -> 2215.6318
A14: 7 | B14: NOP VY | C14: ប្រុស | D14: ស្ថាបនិក | E14: 44996 | F14: 5393.8525 | G14: 64.08 | H14: =F14*0.83% -> 44.768976 | I14: =F14+G14+H14 -> 5502.7015 | K14: =I14-J14 -> 5502.7015
A15: 8 | B15: OU RITHTY | C15: ប្រុស | D15: ស្ថាបនិក | E15: 44994 | F15: 4765.1579 | G15: 50 | H15: =F15*0.83% -> 39.550811 | I15: =F15+G15+H15 -> 4854.7087 | K15: =I15-J15 -> 4854.7087
A16: 9 | B16: SENG RITHY | C16: ប្រុស | D16: សមាជិក | E16: 44991 | F16: 5 | G16: 5 | H16: =F16*0.83% -> 0.0415 | I16: =F16+G16+H16 -> 10.0415 | K16: =I16-J16 -> 10.0415
A17: 10 | B17: OU TEP PHALLIN | C17: ស្រី | D17: សមាជិក | E17: 44988 | F17: 20 | G17: 20 | H17: =F17*0.83% -> 0.166 | I17: =F17+G17+H17 -> 40.166 | K17: =I17-J17 -> 40.166
A18: 11 | B18: YIM BUNTHENG | D18: សមាជិក | E18: 44988 | F18: 10 | G18: 10 | H18: =F18*0.83% -> 0.083 | I18: =F18+G18+H18 -> 20.083 | K18: =I18-J18 -> 20.083
A19: 12 | B19: THENG SAVOEUN | D19: សមាជិក | E19: 44967 | F19: 50 | H19: =F19*0.83% -> 0.415 | I19: =F19+G19+H19 -> 50.415 | K19: =I19-J19 -> 50.415
A20: 13 | B20: OU VANN | D20: សមាជិក | E20: 44967 | F20: 20 | H20: =F20*0.83% -> 0.166 | I20: =F20+G20+H20 -> 20.166 | K20: =I20-J20 -> 20.166
A21: 14 | B21: SIYONN SOTHEARITH | C21: ប្រុស | D21: សមាជិក | E21: 44988 | F21: 100 | G21: 100 | H21: =F21*0.83% -> 0.83 | I21: =F21+G21+H21 -> 200.83 | K21: =I21-J21 -> 200.83
A22: 15 | B22: YEAN REAKSMEY | D22: សមាជិក | E22: 44975 | F22: 10 | H22: =F22*0.83% -> 0.083 | I22: =F22+G22+H22 -> 10.083 | K22: =I22-J22 -> 10.083
A23: 16 | B23: SON PENH | D23: សមាជិក | E23: 44995 | F23: 20 | G23: 20 | H23: =F23*0.83% -> 0.166 | I23: =F23+G23+H23 -> 40.166 | K23: =I23-J23 -> 40.166
A24: 17 | B24: SAM SOMONY | C24: ប្រុស | D24: សមាជិក | E24: 44964 | F24: 202.50381 | G24: 50 | H24: =F24*0.83% -> 1.6807816 | I24: =F24+G24+H24 -> 254.18459 | K24: =I24-J24 -> 254.18459
A25: 18 | B25: KOY MAQUIS | C25: ប្រុស | D25: សមាជិក | E25: 44988 | F25: 15.0415 | G25: 10 | H25: =F25*0.83% -> 0.12484445 | I25: =F25+G25+H25 -> 25.166344 | K25: =I25-J25 -> 25.166344
A26: 19 | B26: Ly Malin | C26: ស្រី | D26: សមាជិក | E26: 44988 | F26: 40.166 | G26: 20 | H26: =F26*0.83% -> 0.3333778 | I26: =F26+G26+H26 -> 60.499378 | K26: =I26-J26 -> 60.499378
A27: 20 | B27: Van Bunna | D27: សមាជិក | E27: 44951 | F27: 10 | H27: =F27*0.83% -> 0.083 | I27: =F27+G27+H27 -> 10.083 | K27: =I27-J27 -> 10.083
A28: 21 | B28: Long Borin | C28: ស្រី | D28: សមាជិក | E28: 44988 | F28: 15.1245 | G28: 15 | H28: =F28*0.83% -> 0.12553335 | I28: =F28+G28+H28 -> 30.250033 | K28: =I28-J28 -> 30.250033
A29: 21 | B29: Chan Theara | C29: ស្រី | D29: សមាជិក | E29: 44993 | F29: 5 | I29: =F29+G29+H29 -> 5 | K29: =I29-J29 -> 5
F31: =SUM(F8:F28) -> 33390.821 | G31: =SUM(G8:G28) -> 517.44 | H31: =SUM(H8:H28) -> 277.14381 | I31: =SUM(I8:I28) -> 34185.404 | J31: =SUM(J8:J28) -> 0 | K31: =SUM(K8:K28) -> 34185.404

Sheet Saving monthly Apr-23
A1: ក្រុម​សន្សំ​ប្រាក់ «សន្សំSANSAM»
A2: ការសន្សំ​ចាប់​ពី​៥ដុល្លារ​ឡើង​ទៅក្នុង​មួយខែ ដោយ​សមាជិក​នឹង​ទទួល​បានការប្រាក់ប្រចាំ​ខែ0.83%
A3: ចំពោះ​សមាជិក​ដែលដាក់ប្រាក់​កម្ចី​គឺក្នុងអត្រា​ការប្រាក់​១០%ក្នុង​មួយឆ្នាំ​សម្រាប់ក្រុម​ប្រឹក្សាភិបាល​ ១៤.៤%ក្នុង​មួយឆ្នាំសម្រាប់​សមាជិកស្នូល ១៨%ក្នុងមួយឆ្នាំ​សម្រាប់​សមាជិក​ធម្មតា ៣%​ក្នុងមួយឆ្នាំ​សម្រាប់​សមាជិក​បញ្ញើ
A4: ការ​ដាក់​ប្រាក់​សន្សំចាប់ពី​ថ្ងៃទី១ដល់ថ្ងៃទី១០រៀងរាល់ខែ
A5: ពេលវេលាទទួល​បាន​កម្ចី​ចន្លោះពីថ្ងៃទី១០ដល់ថ្ងៃទី១៥​រៀងរាល់ខែ
A6: តារាងសន្សំ​ខែ មេសា​ ឆ្នាំ២០២៣
A7: ល.រ | B7: ឈ្មោះ​សមាជិកដាក់សន្សំ​ | C7: ភេទ | D7: តួនាទី​ក្នុង​សន្សំ | E7: ថ្ងៃខែដាក់សន្សំ | F7: ប្រាក់ដើម | G7: ប្រាក់ដាក់សន្សំ | H7: ការប្រាក់ទទួលបាន | I7: សមតុល្យ​សាច់ប្រាក់ | J7: ប្រាក់បានដក | K7: សមតុល្យ​សាច់ប្រាក់ក្រោយដក
A8: 1 | B8: ART THORN | C8: ប្រុស | D8: ស្ថាបនិក | E8: 45027 | F8: 3770.3734 | G8: 17.01 | H8: =F8*0.83% -> 31.294099 | I8: =F8+G8+H8 -> 3818.6775 | K8: =I8-J8 -> 3818.6775
A9: 2 | B9: PECH PISEY | C9: ប្រុស | D9: ស្ថាបនិក | E9: 45027 | F9: 5879.4479 | G9: 30 | H9: =F9*0.83% -> 48.799418 | I9: =F9+G9+H9 -> 5958.2473 | K9: =I9-J9 -> 5958.2473
A10: 3 | B10: HONG REAKSMEY | C10: ប្រុស | D10: ស្ថាបនិក | E10: 45026 | F10: 5618.9274 | G10: 50.53 | H10: =F10*0.83% -> 46.637097 | I10: =F10+G10+H10 -> 5716.0945 | K10: =I10-J10 -> 5716.0945
A11: 4 | B11: SIN PUTHEARY | C11: ស្រី | D11: ស្ថាបនិក | E11: 45026 | F11: 5314.3348 | G11: 0.02 | H11: =F11*0.83% -> 44.108979 | I11: =F11+G11+H11 -> 5358.4637 | K11: =I11-J11 -> 5358.4637
A12: 5 | B12: PAO VORN | C12: ប្រុស | D12: ស្ថាបនិក | E12: 45027 | F12: 257.14519 | G12: 50 | H12: =F12*0.83% -> 2.1343051 | I12: =F12+G12+H12 -> 309.27949 | K12: =I12-J12 -> 309.27949
A13: 6 | B13: SOR MORA | C13: ប្រុស | D13: ស្ថាបនិក | E13: 45023 | F13: 2215.6318 | G13: 8.82 | H13: =F13*0.83% -> 18.389744 | I13: =F13+G13+H13 -> 2242.8415 | K13: =I13-J13 -> 2242.8415
A14: 7 | B14: NOP VY | C14: ប្រុស | D14: ស្ថាបនិក | E14: 45026 | F14: 5502.7015 | G14: 67.4 | H14: =F14*0.83% -> 45.672422 | I14: =F14+G14+H14 -> 5615.7739 | K14: =I14-J14 -> 5615.7739
A15: 8 | B15: OU RITHTY | C15: ប្រុស | D15: ស្ថាបនិក | E15: 45026 | F15: 4854.7087 | G15: 50 | H15: =F15*0.83% -> 40.294083 | I15: =F15+G15+H15 -> 4945.0028 | K15: =I15-J15 -> 4945.0028
A16: 9 | B16: SENG RITHY | C16: ប្រុស | D16: សមាជិក | E16: 45026 | F16: 10.0415 | G16: 5 | H16: =F16*0.83% -> 0.08334445 | I16: =F16+G16+H16 -> 15.124844 | K16: =I16-J16 -> 15.124844
A17: 10 | B17: OU TEP PHALLIN | C17: ប្រុស | D17: សមាជិក | E17: 44988 | F17: 40.166 | H17: =F17*0.83% -> 0.3333778 | I17: =F17+G17+H17 -> 40.499378 | K17: =I17-J17 -> 40.499378
A18: 11 | B18: YIM BUNTHENG | D18: សមាជិក | E18: 44988 | F18: 20.083 | H18: =F18*0.83% -> 0.1666889 | I18: =F18+G18+H18 -> 20.249689 | K18: =I18-J18 -> 20.249689
A19: 12 | B19: THENG SAVOEUN | D19: សមាជិក | E19: 45029 | F19: 50.415 | G19: 25 | H19: =F19*0.83% -> 0.4184445 | I19: =F19+G19+H19 -> 75.833444 | K19: =I19-J19 -> 75.833444
A20: 13 | B20: OU VANN | D20: សមាជិក | E20: 44967 | F20: 20.166 | H20: =F20*0.83% -> 0.1673778 | I20: =F20+G20+H20 -> 20.333378 | K20: =I20-J20 -> 20.333378
A21: 14 | B21: SIYONN SOTHEARITH | C21: ប្រុស | D21: សមាជិក | E21: 45034 | F21: 200.83 | G21: 100 | H21: =F21*0.83% -> 1.666889 | I21: =F21+G21+H21 -> 302.49689 | K21: =I21-J21 -> 302.49689
A22: 15 | B22: YEAN REAKSMEY | D22: សមាជិក | E22: 45029 | F22: 10.083 | G22: 30 | H22: =F22*0.83% -> 0.0836889 | I22: =F22+G22+H22 -> 40.166689 | K22: =I22-J22 -> 40.166689
A23: 16 | B23: SON PENH | D23: សមាជិក | E23: 45040 | F23: 40.166 | G23: 20 | H23: =F23*0.83% -> 0.3333778 | I23: =F23+G23+H23 -> 60.499378 | K23: =I23-J23 -> 60.499378
A24: 17 | B24: SAM SOMONY | C24: ប្រុស | D24: សមាជិក | E24: 45024 | F24: 254.18459 | G24: 25 | H24: =F24*0.83% -> 2.1097321 | I24: =F24+G24+H24 -> 281.29432 | K24: =I24-J24 -> 281.29432
A25: 18 | B25: KOY MAQUIS | C25: ប្រុស | D25: សមាជិក | E25: 44971 | F25: 25.166344 | H25: =F25*0.83% -> 0.20888066 | I25: =F25+G25+H25 -> 25.375225 | K25: =I25-J25 -> 25.375225
A26: 19 | B26: Ly Malin | C26: ស្រី | D26: សមាជិក | E26: 45028 | F26: 60.499378 | G26: 20 | H26: =F26*0.83% -> 0.50214484 | I26: =F26+G26+H26 -> 81.001523 | K26: =I26-J26 -> 81.001523
A27: 20 | B27: Van Bunna | D27: សមាជិក | E27: 45031 | F27: 10.083 | G27: 20 | H27: =F27*0.83% -> 0.0836889 | I27: =F27+G27+H27 -> 30.166689 | K27: =I27-J27 -> 30.166689
A28: 21 | B28: Chan Theara | C28: ស្រី | D28: សមាជិក | E28: 44993 | F28: 5 | H28: =F28*0.83% -> 0.0415 | I28: =F28+G28+H28 -> 5.0415 | K28: =I28-J28 -> 5.0415
A29: 22 | B29: Long Borin | C29: ស្រី | D29: សមាជិក | E29: 44957 | F29: 30.25 | G29: 15 | H29: =F29*0.83% -> 0.251075 | I29: =F29+G29+H29 -> 45.501075 | K29: =I29-J29 -> 45.501075
A30: 23 | B30: SOEUNG SAROEUN | D30: សមាជិក | E30: 45034 | F30: 50 | I30: =F30+G30+H30 -> 50 | K30: =I30-J30 -> 50
F32: =SUM(F8:F30) -> 34240.404 | G32: =SUM(G8:G30) -> 533.78 | H32: =SUM(H8:H30) -> 283.78036 | I32: =SUM(I8:I30) -> 35057.965 | J32: =SUM(J8:J30) -> 0 | K32: =SUM(K8:K30) -> 35057.965

Sheet Saving monthly May-23
A1: ក្រុម​សន្សំ​ប្រាក់ «សន្សំSANSAM»
A2: ការសន្សំ​ចាប់​ពី​៥ដុល្លារ​ឡើង​ទៅក្នុង​មួយខែ ដោយ​សមាជិក​នឹង​ទទួល​បានការប្រាក់ប្រចាំ​ខែ0.83%
A3: ចំពោះ​សមាជិក​ដែលដាក់ប្រាក់​កម្ចី​គឺក្នុងអត្រា​ការប្រាក់​១០%ក្នុង​មួយឆ្នាំ​សម្រាប់ក្រុម​ប្រឹក្សាភិបាល​ ១៤.៤%ក្នុង​មួយឆ្នាំសម្រាប់​សមាជិកស្នូល ១៨%ក្នុងមួយឆ្នាំ​សម្រាប់​សមាជិក​ធម្មតា ៣%​ក្នុងមួយឆ្នាំ​សម្រាប់​សមាជិក​បញ្ញើ
A4: ការ​ដាក់​ប្រាក់​សន្សំចាប់ពី​ថ្ងៃទី១ដល់ថ្ងៃទី១០រៀងរាល់ខែ
A5: ពេលវេលាទទួល​បាន​កម្ចី​ចន្លោះពីថ្ងៃទី១០ដល់ថ្ងៃទី១៥​រៀងរាល់ខែ
A6: តារាងសន្សំ​ខែ ឧសភា​ ឆ្នាំ២០២៣
A7: ល.រ | B7: ឈ្មោះ​សមាជិកដាក់សន្សំ​ | C7: ភេទ | D7: តួនាទី​ក្នុង​សន្សំ | E7: ថ្ងៃខែដាក់សន្សំ | F7: ប្រាក់ដើម | G7: ប្រាក់ដាក់សន្សំ | H7: ការប្រាក់ទទួលបាន | I7: សមតុល្យ​សាច់ប្រាក់ | J7: ប្រាក់បានដក | K7: សមតុល្យ​សាច់ប្រាក់ក្រោយដក
A8: 1 | B8: ART THORN | C8: ប្រុស | D8: ស្ថាបនិក | E8: 45059 | F8: 3818.6775 | G8: 17.74 | H8: =F8*0.83% -> 31.695023 | I8: =F8+G8+H8 -> 3868.1125 | K8: =I8-J8 -> 3868.1125
A9: 2 | B9: PECH PISEY | C9: ប្រុស | D9: ស្ថាបនិក | E9: 45060 | F9: 5958.2473 | G9: 50 | H9: =F9*0.83% -> 49.453453 | I9: =F9+G9+H9 -> 6057.7008 | K9: =I9-J9 -> 6057.7008
A10: 3 | B10: HONG REAKSMEY | C10: ប្រុស | D10: ស្ថាបនិក | E10: 45026 | F10: 5716.0945 | H10: =F10*0.83% -> 47.443584 | I10: =F10+G10+H10 -> 5763.5381 | K10: =I10-J10 -> 5763.5381
A11: 4 | B11: SIN PUTHEARY | C11: ស្រី | D11: ស្ថាបនិក | E11: 45026 | F11: 5358.4637 | H11: =F11*0.83% -> 44.475249 | I11: =F11+G11+H11 -> 5402.939 | K11: =I11-J11 -> 5402.939
A12: 5 | B12: PAO VORN | C12: ប្រុស | D12: ស្ថាបនិក | E12: 45027 | F12: 309.27949 | H12: =F12*0.83% -> 2.5670198 | I12: =F12+G12+H12 -> 311.84651 | K12: =I12-J12 -> 311.84651
A13: 6 | B13: SOR MORA | C13: ប្រុស | D13: ស្ថាបនិក | E13: 45056 | F13: 2242.8415 | G13: 10.54 | H13: =F13*0.83% -> 18.615585 | I13: =F13+G13+H13 -> 2271.9971 | K13: =I13-J13 -> 2271.9971
A14: 7 | B14: NOP VY | C14: ប្រុស | D14: ស្ថាបនិក | E14: 45057 | F14: 5615.7739 | G14: 70.72 | H14: =F14*0.83% -> 46.610923 | I14: =F14+G14+H14 -> 5733.1048 | K14: =I14-J14 -> 5733.1048
A15: 8 | B15: OU RITHTY | C15: ប្រុស | D15: ស្ថាបនិក | E15: 45056 | F15: 4945.0028 | G15: 100 | H15: =F15*0.83% -> 41.043523 | I15: =F15+G15+H15 -> 5086.0463 | K15: =I15-J15 -> 5086.0463
A16: 9 | B16: SENG RITHY | C16: ប្រុស | D16: សមាជិក | E16: 45055 | F16: 15.124844 | G16: 5 | H16: =F16*0.83% -> 0.12553621 | I16: =F16+G16+H16 -> 20.250381 | K16: =I16-J16 -> 20.250381
A17: 10 | B17: OU TEP PHALLIN | C17: ប្រុស | D17: សមាជិក | E17: 45055 | F17: 40.499378 | G17: 20 | H17: =F17*0.83% -> 0.33614484 | I17: =F17+G17+H17 -> 60.835523 | K17: =I17-J17 -> 60.835523
A18: 11 | B18: YIM BUNTHENG | D18: សមាជិក | E18: 44988 | F18: 20.249689 | H18: =F18*0.83% -> 0.16807242 | I18: =F18+G18+H18 -> 20.417761 | K18: =I18-J18 -> 20.417761
A19: 12 | B19: THENG SAVOEUN | D19: សមាជិក | E19: 45029 | F19: 75.833444 | H19: =F19*0.83% -> 0.62941759 | I19: =F19+G19+H19 -> 76.462862 | K19: =I19-J19 -> 76.462862
A20: 13 | B20: OU VANN | D20: សមាជិក | E20: 44967 | F20: 20.333378 | H20: =F20*0.83% -> 0.16876704 | I20: =F20+G20+H20 -> 20.502145 | K20: =I20-J20 -> 20.502145
A21: 14 | B21: SIYONN SOTHEARITH | C21: ប្រុស | D21: សមាជិក | E21: 45049 | F21: 302.49689 | G21: 100 | H21: =F21*0.83% -> 2.5107242 | I21: =F21+G21+H21 -> 405.00761 | K21: =I21-J21 -> 405.00761
A22: 15 | B22: YEAN REAKSMEY | D22: សមាជិក | E22: 45056 | F22: 40.166689 | G22: 10 | H22: =F22*0.83% -> 0.33338352 | I22: =F22+G22+H22 -> 50.500072 | K22: =I22-J22 -> 50.500072
A23: 16 | B23: SON PENH | D23: សមាជិក | E23: 45059 | F23: 60.499378 | G23: 20 | H23: =F23*0.83% -> 0.50214484 | I23: =F23+G23+H23 -> 81.001523 | K23: =I23-J23 -> 81.001523
A24: 17 | B24: SAM SOMONY | C24: ប្រុស | D24: សមាជិក | E24: 45049 | F24: 281.29432 | G24: 25 | H24: =F24*0.83% -> 2.3347429 | I24: =F24+G24+H24 -> 308.62906 | K24: =I24-J24 -> 308.62906
A25: 18 | B25: KOY MAQUIS | C25: ប្រុស | D25: សមាជិក | E25: 45057 | F25: 25.375225 | G25: 10 | H25: =F25*0.83% -> 0.21061437 | I25: =F25+G25+H25 -> 35.585839 | K25: =I25-J25 -> 35.585839
A26: 19 | B26: Ly Malin | C26: ស្រី | D26: សមាជិក | E26: 45056 | F26: 81.001523 | G26: 20 | H26: =F26*0.83% -> 0.67231264 | I26: =F26+G26+H26 -> 101.67384 | K26: =I26-J26 -> 101.67384
A27: 20 | B27: Van Bunna | D27: សមាជិក | E27: 45031 | F27: 30.166689 | H27: =F27*0.83% -> 0.25038352 | I27: =F27+G27+H27 -> 30.417072 | K27: =I27-J27 -> 30.417072
A28: 21 | B28: Chan Theara | C28: ស្រី | D28: សមាជិក | E28: 44993 | F28: 5.0415 | H28: =F28*0.83% -> 0.04184445 | I28: =F28+G28+H28 -> 5.0833445 | K28: =I28-J28 -> 5.0833445
A29: 22 | B29: Long Borin | C29: ស្រី | D29: សមាជិក | E29: 45055 | F29: 45.5 | G29: 15 | H29: =F29*0.83% -> 0.37765 | I29: =F29+G29+H29 -> 60.87765 | K29: =I29-J29 -> 60.87765
A30: 23 | B30: SOEUNG SAROEUN | D30: សមាជិក | E30: 45059 | F30: 50 | G30: 25 | H30: =F30*0.83% -> 0.415 | I30: =F30+G30+H30 -> 75.415 | K30: =I30-J30 -> 75.415
A31: 24 | B31: TUY SYTHIENG | D31: សមាជិក | E31: 45056 | F31: 50 | I31: =F31+G31+H31 -> 50 | K31: =I31-J31 -> 50
A32: 25 | B32: CHHEOUNG VEASNA | D32: សមាជិក | E32: 45058 | F32: 100 | I32: =F32+G32+H32 -> 100 | K32: =I32-J32 -> 100
A33: 26 | B33: OM MANITH | D33: សមាជិក | E33: 45059 | F33: 20 | I33: =F33+G33+H33 -> 20 | K33: =I33-J33 -> 20
A34: 27 | B34: IM SOTHY | D34: សមាជិក | E34: 45060 | F34: 30 | I34: =F34+G34+H34 -> 30 | K34: =I34-J34 -> 30
F36: =SUM(F8:F34) -> 35257.964 | G36: =SUM(G8:G34) -> 499 | H36: =SUM(H8:H34) -> 290.9811 | I36: =SUM(I8:I34) -> 36047.945 | J36: =SUM(J8:J34) -> 0 | K36: =SUM(K8:K34) -> 36047.945

Sheet Saving monthly Jun-23
A1: ក្រុម​សន្សំ​ប្រាក់ «សន្សំSANSAM»
A2: ការសន្សំ​ចាប់​ពី​៥ដុល្លារ​ឡើង​ទៅក្នុង​មួយខែ ដោយ​សមាជិក​នឹង​ទទួល​បានការប្រាក់ប្រចាំ​ខែ0.83%
A3: ចំពោះ​សមាជិក​ដែលដាក់ប្រាក់​កម្ចី​គឺក្នុងអត្រា​ការប្រាក់​១០%ក្នុង​មួយឆ្នាំ​សម្រាប់ក្រុម​ប្រឹក្សាភិបាល​ ១៤.៤%ក្នុង​មួយឆ្នាំសម្រាប់​សមាជិកស្នូល ១៨%ក្នុងមួយឆ្នាំ​សម្រាប់​សមាជិក​ធម្មតា ៣%​ក្នុងមួយឆ្នាំ​សម្រាប់​សមាជិក​បញ្ញើ
A4: ការ​ដាក់​ប្រាក់​សន្សំចាប់ពី​ថ្ងៃទី១ដល់ថ្ងៃទី១០រៀងរាល់ខែ
A5: ពេលវេលាទទួល​បាន​កម្ចី​ចន្លោះពីថ្ងៃទី១០ដល់ថ្ងៃទី១៥​រៀងរាល់ខែ
A6: តារាងសន្សំ​ខែ មិថុនា​ ឆ្នាំ២០២៣
A7: ល.រ | B7: ឈ្មោះ​សមាជិកដាក់សន្សំ​ | C7: ភេទ | D7: តួនាទី​ក្នុង​សន្សំ | E7: ថ្ងៃខែដាក់សន្សំ | F7: ប្រាក់ដើម | G7: ប្រាក់ដាក់សន្សំ | H7: ការប្រាក់ទទួលបាន | I7: សមតុល្យ​សាច់ប្រាក់ | J7: ប្រាក់បានដក | K7: សមតុល្យ​សាច់ប្រាក់ក្រោយដក
A8: 1 | B8: ART THORN | C8: ប្រុស | D8: ស្ថាបនិក | E8: 45089 | F8: 3868.1125 | G8: 18.47 | H8: =F8*0.83% -> 32.105334 | I8: =F8+G8+H8 -> 3918.6879 | K8: =I8-J8 -> 3918.6879
A9: 2 | B9: PECH PISEY | C9: ប្រុស | D9: ស្ថាបនិក | E9: 45060 | F9: 6057.7008 | H9: =F9*0.83% -> 50.278917 | I9: =F9+G9+H9 -> 6107.9797 | K9: =I9-J9 -> 6107.9797
A10: 3 | B10: HONG REAKSMEY | C10: ប្រុស | D10: ស្ថាបនិក | E10: 45087 | F10: 5763.5381 | G10: 50 | H10: =F10*0.83% -> 47.837366 | I10: =F10+G10+H10 -> 5861.3754 | K10: =I10-J10 -> 5861.3754
A11: 4 | B11: SIN PUTHEARY | C11: ស្រី | D11: ស្ថាបនិក | E11: 45026 | F11: 5402.939 | H11: =F11*0.83% -> 44.844394 | I11: =F11+G11+H11 -> 5447.7834 | K11: =I11-J11 -> 5447.7834
A12: 5 | B12: PAO VORN | C12: ប្រុស | D12: ស្ថាបនិក | E12: 45087 | F12: 311.84651 | G12: 30 | H12: =F12*0.83% -> 2.5883261 | I12: =F12+G12+H12 -> 344.43484 | K12: =I12-J12 -> 344.43484
A13: 6 | B13: SOR MORA | C13: ប្រុស | D13: ស្ថាបនិក | E13: 45087 | F13: 2271.9971 | G13: 12.27 | H13: =F13*0.83% -> 18.857576 | I13: =F13+G13+H13 -> 2303.1247 | K13: =I13-J13 -> 2303.1247
A14: 7 | B14: NOP VY | C14: ប្រុស | D14: ស្ថាបនិក | E14: 45087 | F14: 5733.1048 | G14: 74.04 | H14: =F14*0.83% -> 47.58477 | I14: =F14+G14+H14 -> 5854.7296 | K14: =I14-J14 -> 5854.7296
A15: 8 | B15: OU RITHTY | C15: ប្រុស | D15: ស្ថាបនិក | E15: 45087 | F15: 5086.0463 | G15: 100 | H15: =F15*0.83% -> 42.214185 | I15: =F15+G15+H15 -> 5228.2605 | K15: =I15-J15 -> 5228.2605
A16: 9 | B16: SENG RITHY | C16: ប្រុស | D16: សមាជិក | E16: 45084 | F16: 20.250381 | G16: 5 | H16: =F16*0.83% -> 0.16807816 | I16: =F16+G16+H16 -> 25.418459 | K16: =I16-J16 -> 25.418459
A17: 10 | B17: OU TEP PHALLIN | C17: ស្រី | D17: សមាជិក | E17: 45084 | F17: 60.835523 | G17: 20 | H17: =F17*0.83% -> 0.50493484 | I17: =F17+G17+H17 -> 81.340457 | K17: =I17-J17 -> 81.340457
A18: 11 | B18: YIM BUNTHENG | D18: សមាជិក | E18: 45086 | F18: 20.417761 | G18: 10 | H18: =F18*0.83% -> 0.16946742 | I18: =F18+G18+H18 -> 30.587229 | K18: =I18-J18 -> 30.587229
A19: 12 | B19: THENG SAVOEUN | D19: សមាជិក | E19: 45029 | F19: 76.462862 | H19: =F19*0.83% -> 0.63464176 | I19: =F19+G19+H19 -> 77.097504 | K19: =I19-J19 -> 77.097504
A20: 13 | B20: OL VANN | D20: សមាជិក | E20: 45088 | F20: 20.502145 | G20: 20 | H20: =F20*0.83% -> 0.1701678 | I20: =F20+G20+H20 -> 40.672313 | K20: =I20-J20 -> 40.672313
A21: 14 | B21: SIYONN SOTHEARITH | C21: ប្រុស | D21: សមាជិក | E21: 45079 | F21: 405.00761 | G21: 100 | H21: =F21*0.83% -> 3.3615632 | I21: =F21+G21+H21 -> 508.36918 | K21: =I21-J21 -> 508.36918
A22: 15 | B22: YEAN REAKSMEY | D22: សមាជិក | E22: 45056 | F22: 50.500072 | H22: =F22*0.83% -> 0.4191506 | I22: =F22+G22+H22 -> 50.919223 | K22: =I22-J22 -> 50.919223
A23: 16 | B23: SON PENH | D23: សមាជិក | E23: 45059 | F23: 81.001523 | G23: 20 | H23: =F23*0.83% -> 0.67231264 | I23: =F23+G23+H23 -> 101.67384 | K23: =I23-J23 -> 101.67384
A24: 17 | B24: SAM SOMONY | C24: ប្រុស | D24: សមាជិក | E24: 45083 | F24: 308.62906 | G24: 25 | H24: =F24*0.83% -> 2.5616212 | I24: =F24+G24+H24 -> 336.19068 | K24: =I24-J24 -> 336.19068
A25: 18 | B25: KOY MAQUIS | C25: ប្រុស | D25: សមាជិក | E25: 45085 | F25: 35.585839 | G25: 10 | H25: =F25*0.83% -> 0.29536247 | I25: =F25+G25+H25 -> 45.881202 | K25: =I25-J25 -> 45.881202
A26: 19 | B26: Ly Malin | C26: ស្រី | D26: សមាជិក | E26: 45083 | F26: 101.67384 | G26: 20 | H26: =F26*0.83% -> 0.84389283 | I26: =F26+G26+H26 -> 122.51773 | K26: =I26-J26 -> 122.51773
A27: 20 | B27: Van Bunna | D27: សមាជិក | E27: 45088 | F27: 30.417072 | G27: 20 | H27: =F27*0.83% -> 0.2524617 | I27: =F27+G27+H27 -> 50.669534 | K27: =I27-J27 -> 50.669534
A28: 21 | B28: Chan Theara | C28: ស្រី | D28: សមាជិក | E28: 44993 | F28: 5.0833445 | H28: =F28*0.83% -> 0.042191759 | I28: =F28+G28+H28 -> 5.1255362 | K28: =I28-J28 -> 5.1255362
A29: 22 | B29: Long Borin | C29: ស្រី | D29: សមាជិក | E29: 45086 | F29: 60.87765 | G29: 15 | H29: =F29*0.83% -> 0.50528449 | I29: =F29+G29+H29 -> 76.382935 | K29: =I29-J29 -> 76.382935
A30: 23 | B30: SOEUNG SAROEUN | D30: សមាជិក | E30: 45059 | F30: 75.415 | H30: =F30*0.83% -> 0.6259445 | I30: =F30+G30+H30 -> 76.040944 | K30: =I30-J30 -> 76.040944
A31: 24 | B31: TUY SYTHIENG | D31: សមាជិក | E31: 45088 | F31: 50 | G31: 50 | H31: =F31*0.83% -> 0.415 | I31: =F31+G31+H31 -> 100.415 | K31: =I31-J31 -> 100.415
A32: 25 | B32: CHHEOUNG VEASNA | D32: សមាជិក | E32: 45087 | F32: 100 | G32: 10 | H32: =F32*0.83% -> 0.83 | I32: =F32+G32+H32 -> 110.83 | K32: =I32-J32 -> 110.83
A33: 26 | B33: OM MANITH | D33: សមាជិក | E33: 45059 | F33: 20 | H33: =F33*0.83% -> 0.166 | I33: =F33+G33+H33 -> 20.166 | K33: =I33-J33 -> 20.166
A34: 27 | B34: SOTHY | D34: សមាជិក | E34: 45060 | F34: 30 | H34: =F34*0.83% -> 0.249 | I34: =F34+G34+H34 -> 30.249 | K34: =I34-J34 -> 30.249
A35: 28 | B35: Pa Chanroeun | C35: ប្រុស | D35: សមាជិក | E35: 45085 | F35: 200 | H35: =F35*0.83% -> 1.66 | I35: =F35+G35+H35 -> 201.66 | K35: =I35-J35 -> 201.66
F37: =SUM(F8:F35) -> 36247.945 | G37: =SUM(G8:G35) -> 609.78 | H37: =SUM(H8:H35) -> 300.85794 | I37: =SUM(I8:I35) -> 37158.583 | J37: =SUM(J8:J35) -> 0 | K37: =SUM(K8:K35) -> 37158.583

Sheet Saving Monthly Jul-23
A1: ក្រុម​សន្សំ​ប្រាក់ «សន្សំSANSAM»
A2: ការសន្សំ​ចាប់​ពី​៥ដុល្លារ​ឡើង​ទៅក្នុង​មួយខែ ដោយ​សមាជិក​នឹង​ទទួល​បានការប្រាក់ប្រចាំ​ខែ0.83%
A3: ចំពោះ​សមាជិក​ដែលដាក់ប្រាក់​កម្ចី​គឺក្នុងអត្រា​ការប្រាក់​១០%ក្នុង​មួយឆ្នាំ​សម្រាប់ក្រុម​ប្រឹក្សាភិបាល​ ១៤.៤%ក្នុង​មួយឆ្នាំសម្រាប់​សមាជិកស្នូល ១៨%ក្នុងមួយឆ្នាំ​សម្រាប់​សមាជិក​ធម្មតា ៣%​ក្នុងមួយឆ្នាំ​សម្រាប់​សមាជិក​បញ្ញើ
A4: ការ​ដាក់​ប្រាក់​សន្សំចាប់ពី​ថ្ងៃទី១ដល់ថ្ងៃទី១០រៀងរាល់ខែ
A5: ពេលវេលាទទួល​បាន​កម្ចី​ចន្លោះពីថ្ងៃទី១០ដល់ថ្ងៃទី១៥​រៀងរាល់ខែ
A6: តារាងសន្សំ​ខែ កក្កដា​ ឆ្នាំ២០២៣
A7: ល.រ | B7: ឈ្មោះ​សមាជិកដាក់សន្សំ​ | C7: ភេទ | D7: តួនាទី​ក្នុង​សន្សំ | E7: ថ្ងៃខែដាក់សន្សំ | F7: ប្រាក់ដើម | G7: ប្រាក់ដាក់សន្សំ | H7: ការប្រាក់ទទួលបាន | I7: សមតុល្យ​សាច់ប្រាក់ | J7: ប្រាក់បានដក | K7: សមតុល្យ​សាច់ប្រាក់ក្រោយដក
A8: 1 | B8: ART THORN | C8: ប្រុស | D8: ស្ថាបនិក | E8: 45118 | F8: 3918.6879 | G8: 19.21 | H8: =F8*0.83% -> 32.525109 | I8: =F8+G8+H8 -> 3970.423 | K8: =I8-J8 -> 3970.423
A9: 2 | B9: PECH PISEY | C9: ប្រុស | D9: ស្ថាបនិក | E9: 45122 | F9: 6107.9797 | G9: 30 | H9: =F9*0.83% -> 50.696232 | I9: =F9+G9+H9 -> 6188.6759 | K9: =I9-J9 -> 6188.6759
A10: 3 | B10: HONG REAKSMEY | C10: ប្រុស | D10: ស្ថាបនិក | E10: 45114 | F10: 5861.3754 | G10: 50 | H10: =F10*0.83% -> 48.649416 | I10: =F10+G10+H10 -> 5960.0248 | K10: =I10-J10 -> 5960.0248
A11: 4 | B11: SIN PUTHEARY | C11: ស្រី | D11: ស្ថាបនិក | E11: 45026 | F11: 5447.7834 | H11: =F11*0.83% -> 45.216602 | I11: =F11+G11+H11 -> 5493 | K11: =I11-J11 -> 5493
A12: 5 | B12: PAO VORN | C12: ប្រុស | D12: ស្ថាបនិក | E12: 45087 | F12: 344.43484 | H12: =F12*0.83% -> 2.8588092 | I12: =F12+G12+H12 -> 347.29365 | K12: =I12-J12 -> 347.29365
A13: 6 | B13: SOR MORA | C13: ប្រុស | D13: ស្ថាបនិក | E13: 45114 | F13: 2303.1247 | G13: 3.44 | H13: =F13*0.83% -> 19.115935 | I13: =F13+G13+H13 -> 2325.6806 | K13: =I13-J13 -> 2325.6806
A14: 7 | B14: NOP VY | C14: ប្រុស | D14: ស្ថាបនិក | E14: 45116 | F14: 5854.7296 | G14: 27.36 | H14: =F14*0.83% -> 48.594255 | I14: =F14+G14+H14 -> 5930.6838 | K14: =I14-J14 -> 5930.6838
A15: 8 | B15: OU RITHTY | C15: ប្រុស | D15: ស្ថាបនិក | E15: 45114 | F15: 5228.2605 | G15: 100 | H15: =F15*0.83% -> 43.394562 | I15: =F15+G15+H15 -> 5371.6551 | K15: =I15-J15 -> 5371.6551
A16: 9 | B16: SENG RITHY | C16: ប្រុស | D16: សមាជិក | E16: 45114 | F16: 25.418459 | G16: 5 | H16: =F16*0.83% -> 0.21097321 | I16: =F16+G16+H16 -> 30.629432 | K16: =I16-J16 -> 30.629432
A17: 10 | B17: OU TEP PHALLIN | C17: ប្រុស | D17: សមាជិក | E17: 45086 | F17: 81.340457 | H17: =F17*0.83% -> 0.6751258 | I17: =F17+G17+H17 -> 82.015583 | K17: =I17-J17 -> 82.015583
A18: 11 | B18: YIM BUNTHENG | D18: សមាជិក | E18: 45114 | F18: 30.587229 | G18: 10 | H18: =F18*0.83% -> 0.253874 | I18: =F18+G18+H18 -> 40.841103 | K18: =I18-J18 -> 40.841103
A19: 12 | B19: THENG SAVOEUN | D19: សមាជិក | E19: 45029 | F19: 77.097504 | H19: =F19*0.83% -> 0.63990928 | I19: =F19+G19+H19 -> 77.737413 | K19: =I19-J19 -> 77.737413
A20: 13 | B20: UL VANN | D20: សមាជិក | E20: 45118 | F20: 40.672313 | G20: 20 | H20: =F20*0.83% -> 0.33758019 | I20: =F20+G20+H20 -> 61.009893 | K20: =I20-J20 -> 61.009893
A21: 14 | B21: SIYONN SOTHEARITH | C21: ប្រុស | D21: សមាជិក | E21: 45079 | F21: 508.36918 | H21: =F21*0.83% -> 4.2194642 | I21: =F21+G21+H21 -> 512.58864 | K21: =I21-J21 -> 512.58864
A22: 15 | B22: YEAN REAKSMEY | D22: សមាជិក | E22: 45056 | F22: 50.919223 | H22: =F22*0.83% -> 0.42262955 | I22: =F22+G22+H22 -> 51.341853 | K22: =I22-J22 -> 51.341853
A23: 16 | B23: SON PENH | D23: សមាជិក | E23: 45104 | F23: 101.67384 | G23: 20 | H23: =F23*0.83% -> 0.84389283 | I23: =F23+G23+H23 -> 122.51773 | K23: =I23-J23 -> 122.51773
A24: 17 | B24: SAM SOMONY | C24: ប្រុស | D24: សមាជិក | E24: 45114 | F24: 336.19068 | G24: 25 | H24: =F24*0.83% -> 2.7903827 | I24: =F24+G24+H24 -> 363.98107 | K24: =I24-J24 -> 363.98107
A25: 18 | B25: KOY MAQUIS | C25: ប្រុស | D25: សមាជិក | E25: 45115 | F25: 45.881202 | G25: 10 | H25: =F25*0.83% -> 0.38081398 | I25: =F25+G25+H25 -> 56.262016 | K25: =I25-J25 -> 56.262016
A26: 19 | B26: Ly Malin | C26: ស្រី | D26: សមាជិក | E26: 45114 | F26: 122.51773 | G26: 20 | H26: =F26*0.83% -> 1.0168971 | I26: =F26+G26+H26 -> 143.53463 | K26: =I26-J26 -> 143.53463
A27: 20 | B27: Van Bunna | D27: សមាជិក | E27: 45088 | F27: 50.669534 | H27: =F27*0.83% -> 0.42055713 | I27: =F27+G27+H27 -> 51.090091 | K27: =I27-J27 -> 51.090091
A28: 21 | B28: Chan Theara | C28: ស្រី | D28: សមាជិក | E28: 44993 | F28: 5.1255362 | H28: =F28*0.83% -> 0.042541951 | I28: =F28+G28+H28 -> 5.1680782 | K28: =I28-J28 -> 5.1680782
A29: 22 | B29: Long Borin | C29: ស្រី | D29: សមាជិក | E29: 45114 | F29: 76.382934 | G29: 15 | H29: =F29*0.83% -> 0.63397836 | I29: =F29+G29+H29 -> 92.016913 | K29: =I29-J29 -> 92.016913
A30: 23 | B30: SOEUNG SAROEUN | D30: សមាជិក | E30: 45059 | F30: 76.040945 | H30: =F30*0.83% -> 0.63113984 | I30: =F30+G30+H30 -> 76.672084 | K30: =I30-J30 -> 76.672084
A31: 24 | B31: TUY SYTHIENG | D31: សមាជិក | E31: 45088 | F31: 100.415 | H31: =F31*0.83% -> 0.8334445 | I31: =F31+G31+H31 -> 101.24844 | K31: =I31-J31 -> 101.24844
A32: 25 | B32: CHHEOUNG VEASNA | D32: សមាជិក | E32: 45118 | F32: 110.83 | G32: 100 | H32: =F32*0.83% -> 0.919889 | I32: =F32+G32+H32 -> 211.74989 | K32: =I32-J32 -> 211.74989
A33: 26 | B33: OM MANITH | D33: សមាជិក | E33: 45059 | F33: 20.166 | H33: =F33*0.83% -> 0.1673778 | I33: =F33+G33+H33 -> 20.333378 | K33: =I33-J33 -> 20.333378
A34: 27 | B34: SOTHY | D34: សមាជិក | E34: 45060 | F34: 30.249 | H34: =F34*0.83% -> 0.2510667 | I34: =F34+G34+H34 -> 30.500067 | K34: =I34-J34 -> 30.500067
A35: 28 | B35: Pa Chanroeun | C35: ប្រុស | D35: សមាជិក | E35: 45085 | F35: 201.66 | I35: =F35+G35+H35 -> 201.66 | K35: =I35-J35 -> 201.66
F37: =SUM(F8:F35) -> 37158.583 | G37: =SUM(G8:G35) -> 455.01 | H37: =SUM(H8:H35) -> 306.74246 | I37: =SUM(I8:I35) -> 37920.335 | J37: =SUM(J8:J35) -> 0 | K37: =SUM(K8:K35) -> 37920.335

Sheet Saving Monthly Aug-23
A1: ក្រុម​សន្សំ​ប្រាក់ «សន្សំSANSAM»
A2: ការសន្សំ​ចាប់​ពី​៥ដុល្លារ​ឡើង​ទៅក្នុង​មួយខែ ដោយ​សមាជិក​នឹង​ទទួល​បានការប្រាក់ប្រចាំ​ខែ0.83%
A3: ចំពោះ​សមាជិក​ដែលដាក់ប្រាក់​កម្ចី​គឺក្នុងអត្រា​ការប្រាក់​១០%ក្នុង​មួយឆ្នាំ​សម្រាប់ក្រុម​ប្រឹក្សាភិបាល​ ១៤.៤%ក្នុង​មួយឆ្នាំសម្រាប់​សមាជិកស្នូល ១៨%ក្នុងមួយឆ្នាំ​សម្រាប់​សមាជិក​ធម្មតា ៣%​ក្នុងមួយឆ្នាំ​សម្រាប់​សមាជិក​បញ្ញើ
A4: ការ​ដាក់​ប្រាក់​សន្សំចាប់ពី​ថ្ងៃទី១ដល់ថ្ងៃទី១០រៀងរាល់ខែ
A5: ពេលវេលាទទួល​បាន​កម្ចី​ចន្លោះពីថ្ងៃទី១០ដល់ថ្ងៃទី១៥​រៀងរាល់ខែ
A6: តារាងសន្សំ​ខែ សីហា ឆ្នាំ២០២៣
A7: ល.រ | B7: ឈ្មោះ​សមាជិកដាក់សន្សំ​ | C7: ភេទ | D7: តួនាទី​ក្នុង​សន្សំ | E7: ថ្ងៃខែដាក់សន្សំ | F7: ប្រាក់ដើម | G7: ប្រាក់ដាក់សន្សំ | H7: ការប្រាក់ទទួលបាន | I7: សមតុល្យ​សាច់ប្រាក់ | J7: ប្រាក់បានដក | K7: សមតុល្យ​សាច់ប្រាក់ក្រោយដក
A8: 1 | B8: ART THORN | C8: ប្រុស | D8: ស្ថាបនិក | E8: 45149 | F8: 3970.423 | G8: 9.94 | H8: =F8*0.83% -> 32.954511 | I8: =F8+G8+H8 -> 4013.3175 | K8: =I8-J8 -> 4013.3175
A9: 2 | B9: PECH PISEY | C9: ប្រុស | D9: ស្ថាបនិក | E9: 45146 | F9: 6188.6759 | G9: 50 | H9: =F9*0.83% -> 51.36601 | I9: =F9+G9+H9 -> 6290.0419 | K9: =I9-J9 -> 6290.0419
A10: 3 | B10: HONG REAKSMEY | C10: ប្រុស | D10: ស្ថាបនិក | E10: 45114 | F10: 5960.0248 | H10: =F10*0.83% -> 49.468206 | I10: =F10+G10+H10 -> 6009.4931 | K10: =I10-J10 -> 6009.4931
A11: 4 | B11: SIN PUTHEARY | C11: ស្រី | D11: ស្ថាបនិក | E11: 45149 | F11: 5493 | G11: 2 | H11: =F11*0.83% -> 45.5919 | I11: =F11+G11+H11 -> 5540.5919 | K11: =I11-J11 -> 5540.5919
A12: 5 | B12: PAO VORN | C12: ប្រុស | D12: ស្ថាបនិក | E12: 45087 | F12: 347.29365 | H12: =F12*0.83% -> 2.8825373 | I12: =F12+G12+H12 -> 350.17619 | K12: =I12-J12 -> 350.17619
A13: 6 | B13: SOR MORA | C13: ប្រុស | D13: ស្ថាបនិក | E13: 45114 | F13: 2325.6806 | H13: =F13*0.83% -> 19.303149 | I13: =F13+G13+H13 -> 2344.9838 | K13: =I13-J13 -> 2344.9838
A14: 7 | B14: NOP VY | C14: ប្រុស | D14: ស្ថាបនិក | E14: 45148 | F14: 5930.6838 | G14: 30.68 | H14: =F14*0.83% -> 49.224676 | I14: =F14+G14+H14 -> 6010.5885 | K14: =I14-J14 -> 6010.5885
A15: 8 | B15: OU RITHTY | C15: ប្រុស | D15: ស្ថាបនិក | E15: 45146 | F15: 5371.6551 | G15: 100 | H15: =F15*0.83% -> 44.584737 | I15: =F15+G15+H15 -> 5516.2398 | K15: =I15-J15 -> 5516.2398
A16: 9 | B16: SENG RITHY | C16: ប្រុស | D16: សមាជិក | E16: 45147 | F16: 30.629432 | G16: 5 | H16: =F16*0.83% -> 0.25422429 | I16: =F16+G16+H16 -> 35.883656 | K16: =I16-J16 -> 35.883656
A17: 10 | B17: OU TEP PHALLIN | C17: ប្រុស | D17: សមាជិក | E17: 45086 | F17: 82.015583 | G17: 20 | H17: =F17*0.83% -> 0.68072934 | I17: =F17+G17+H17 -> 102.69631 | K17: =I17-J17 -> 102.69631
A18: 11 | B18: YIM BUNTHENG | D18: សមាជិក | E18: 45147 | F18: 40.841103 | G18: 10 | H18: =F18*0.83% -> 0.33898115 | I18: =F18+G18+H18 -> 51.180084 | K18: =I18-J18 -> 51.180084
A19: 12 | B19: THENG SAVOEUN | D19: សមាជិក | E19: 45029 | F19: 77.737413 | H19: =F19*0.83% -> 0.64522053 | I19: =F19+G19+H19 -> 78.382634 | K19: =I19-J19 -> 78.382634
A20: 13 | B20: UL VANN | D20: សមាជិក | E20: 45148 | F20: 61.009893 | G20: 20 | H20: =F20*0.83% -> 0.50638211 | I20: =F20+G20+H20 -> 81.516275 | K20: =I20-J20 -> 81.516275
A21: 14 | B21: SIYONN SOTHEARITH | C21: ប្រុស | D21: សមាជិក | E21: 45079 | F21: 512.58864 | H21: =F21*0.83% -> 4.2544857 | I21: =F21+G21+H21 -> 516.84313 | K21: =I21-J21 -> 516.84313
A22: 15 | B22: YEAN REAKSMEY | D22: សមាជិក | E22: 45056 | F22: 51.341853 | H22: =F22*0.83% -> 0.42613738 | I22: =F22+G22+H22 -> 51.76799 | K22: =I22-J22 -> 51.76799
A23: 16 | B23: SON PENH | D23: សមាជិក | E23: 45104 | F23: 122.51773 | H23: =F23*0.83% -> 1.0168971 | I23: =F23+G23+H23 -> 123.53463 | K23: =I23-J23 -> 123.53463
A24: 17 | B24: SAM SOMONY | C24: ប្រុស | D24: សមាជិក | E24: 45143 | F24: 363.98107 | G24: 25 | H24: =F24*0.83% -> 3.0210429 | I24: =F24+G24+H24 -> 392.00211 | K24: =I24-J24 -> 392.00211
A25: 18 | B25: KOY MAQUIS | C25: ប្រុស | D25: សមាជិក | E25: 45147 | F25: 56.262016 | G25: 10 | H25: =F25*0.83% -> 0.46697473 | I25: =F25+G25+H25 -> 66.728991 | K25: =I25-J25 -> 66.728991
A26: 19 | B26: Ly Malin | C26: ស្រី | D26: សមាជិក | E26: 45147 | F26: 143.53463 | G26: 20 | H26: =F26*0.83% -> 1.1913374 | I26: =F26+G26+H26 -> 164.72596 | K26: =I26-J26 -> 164.72596
A27: 20 | B27: Van Bunna | D27: សមាជិក | E27: 45088 | F27: 51.090091 | H27: =F27*0.83% -> 0.42404776 | I27: =F27+G27+H27 -> 51.514139 | K27: =I27-J27 -> 51.514139
A28: 21 | B28: Chan Theara | C28: ស្រី | D28: សមាជិក | E28: 44993 | F28: 5.1680782 | H28: =F28*0.83% -> 0.042895049 | I28: =F28+G28+H28 -> 5.2109732 | K28: =I28-J28 -> 5.2109732
A29: 22 | B29: Long Borin | C29: ស្រី | D29: សមាជិក | E29: 45140 | F29: 92.02 | G29: 15 | H29: =F29*0.83% -> 0.763766 | I29: =F29+G29+H29 -> 107.78377 | K29: =I29-J29 -> 107.78377
A30: 23 | B30: SOEUNG SAROEUN | D30: សមាជិក | E30: 45059 | F30: 76.672084 | H30: =F30*0.83% -> 0.6363783 | I30: =F30+G30+H30 -> 77.308463 | K30: =I30-J30 -> 77.308463
A31: 24 | B31: TUY SYTHIENG | D31: សមាជិក | E31: 45146 | F31: 101.24844 | G31: 100 | H31: =F31*0.83% -> 0.84036209 | I31: =F31+G31+H31 -> 202.08881 | K31: =I31-J31 -> 202.08881
A32: 25 | B32: CHHEOUNG VEASNA | D32: សមាជិក | E32: 45118 | F32: 211.74989 | H32: =F32*0.83% -> 1.7575241 | I32: =F32+G32+H32 -> 213.50741 | K32: =I32-J32 -> 213.50741
A33: 26 | B33: OM MANITH | D33: សមាជិក | E33: 45059 | F33: 20.333378 | H33: =F33*0.83% -> 0.16876704 | I33: =F33+G33+H33 -> 20.502145 | K33: =I33-J33 -> 20.502145
A34: 27 | B34: SOTHY | D34: សមាជិក | E34: 45060 | F34: 30.500067 | H34: =F34*0.83% -> 0.25315055 | I34: =F34+G34+H34 -> 30.753217 | K34: =I34-J34 -> 30.753217
A35: 28 | B35: Pa Chanroeun | C35: ប្រុស | D35: សមាជិក | E35: 45085 | F35: 201.66 | I35: =F35+G35+H35 -> 201.66 | K35: =I35-J35 -> 201.66
F37: =SUM(F8:F35) -> 37920.338 | G37: =SUM(G8:G35) -> 417.62 | H37: =SUM(H8:H35) -> 313.06503 | I37: =SUM(I8:I35) -> 38651.023 | J37: =SUM(J8:J35) -> 0 | K37: =SUM(K8:K35) -> 38651.023

Sheet Saving Monthly Sep-23
A1: SANSAM SAVING GROUP
A2: SAVING FROM 5USD PER MONTH BY GETTING INTEREST 10% PER YEAR
A3: SAVING DEPOSIT FROM 1ST - 10TH EVERY MONTH
A4: ACCESSIBLE LOAN ON 15TH EACH MONTH
A5: SAVING IN SEPTEMBER 2023
A6: NO | B6: NAME | C6: SEX | D6: ROLE | E6: SAVING DATE | F6: TEAM LEADER | G6: CAPITAL | H6: SAVING | I6: INTEREST | J6: BALANCE | K6: WITHDRAWAL | L6: TOTAL
A7: 1 | B7: ART THORN | C7: M | D7: FOUNDER | E7: 45149 | G7: 4013.3175 | H7: 10.67 | I7: =G7*0.83% -> 33.310535 | J7: =G7+H7+I7 -> 4057.298 | L7: =J7-K7 -> 4057.298
A8: 2 | B8: PECH PISEY | C8: M | D8: FOUNDER | E8: 45173 | G8: 6290.0419 | H8: 50 | I8: =G8*0.83% -> 52.207348 | J8: =G8+H8+I8 -> 6392.2493 | L8: =J8-K8 -> 6392.2493
A9: 3 | B9: HONG REAKSMEY | C9: M | D9: FOUNDER | E9: 45171 | G9: 6009.4931 | H9: 100 | I9: =G9*0.83% -> 49.878792 | J9: =G9+H9+I9 -> 6159.3718 | L9: =J9-K9 -> 6159.3718
A10: 4 | B10: SIN PUTHEARY | C10: F | D10: FOUNDER | E10: 45171 | G10: 5540.5919 | H10: 37.94 | I10: =G10*0.83% -> 45.986913 | J10: =G10+H10+I10 -> 5624.5188 | L10: =J10-K10 -> 5624.5188
A11: 5 | B11: PAO VORN | C11: M | D11: FOUNDER | E11: 45087 | G11: 350.17619 | I11: =G11*0.83% -> 2.9064623 | J11: =G11+H11+I11 -> 353.08265 | L11: =J11-K11 -> 353.08265
A12: 6 | B12: SOR MORA | C12: M | D12: FOUNDER | E12: 45181 | G12: 2344.9838 | H12: 5.75 | I12: =G12*0.83% -> 19.463365 | J12: =G12+H12+I12 -> 2370.1971 | L12: =J12-K12 -> 2370.1971
A13: 7 | B13: NOP VY | C13: M | D13: FOUNDER | E13: 45179 | G13: 6010.5885 | H13: 34 | I13: =G13*0.83% -> 49.887885 | J13: =G13+H13+I13 -> 6094.4764 | L13: =J13-K13 -> 6094.4764
A14: 8 | B14: OU RITHTY | C14: M | D14: FOUNDER | E14: 45171 | G14: 5516.2398 | H14: 50 | I14: =G14*0.83% -> 45.784791 | J14: =G14+H14+I14 -> 5612.0246 | L14: =J14-K14 -> 5612.0246
A15: 9 | B15: SENG RITHY | C15: M | D15: MEMBER | E15: 45173 | F15: NOP VY | G15: 35.883656 | H15: 5 | I15: =G15*0.83% -> 0.29783435 | J15: =G15+H15+I15 -> 41.181491 | L15: =J15-K15 -> 41.181491
A16: 10 | B16: OU TEP PHALLIN | C16: F | D16: MEMBER | E16: 45171 | F16: OU RITHY | G16: 102.69631 | H16: 20 | I16: =G16*0.83% -> 0.85237939 | J16: =G16+H16+I16 -> 123.54869 | L16: =J16-K16 -> 123.54869
A17: 11 | B17: YIM BUNTHENG | C17: M | D17: MEMBER | E17: 45147 | F17: HONG REAKSMEY | G17: 51.180084 | I17: =G17*0.83% -> 0.4247947 | J17: =G17+H17+I17 -> 51.604879 | L17: =J17-K17 -> 51.604879
A18: 12 | B18: THENG SAVOEUN | C18: M | D18: MEMBER | E18: 45029 | F18: NOP VY | G18: 78.382634 | I18: =G18*0.83% -> 0.65057586 | J18: =G18+H18+I18 -> 79.03321 | L18: =J18-K18 -> 79.03321
A19: 13 | B19: UL VANN | C19: M | D19: MEMBER | E19: 36770 | F19: NOP VY | G19: 81.516275 | H19: 20 | I19: =G19*0.83% -> 0.67658508 | J19: =G19+H19+I19 -> 102.19286 | L19: =J19-K19 -> 102.19286
A20: 14 | B20: SIYONN SOTHEARITH | C20: M | D20: MEMBER | E20: 45079 | F20: HONG REAKSMEY | G20: 516.84313 | I20: =G20*0.83% -> 4.2897979 | J20: =G20+H20+I20 -> 521.13292 | L20: =J20-K20 -> 521.13292
A21: 15 | B21: YEAN REAKSMEY | C21: M | D21: MEMBER | E21: 45174 | F21: PECH PISEY | G21: 51.76799 | H21: 15 | I21: =G21*0.83% -> 0.42967432 | J21: =G21+H21+I21 -> 67.197664 | L21: =J21-K21 -> 67.197664
A22: 16 | B22: SON PENH | C22: M | D22: MEMBER | E22: 45170 | F22: PECH PISEY | G22: 123.53463 | H22: 40 | I22: =G22*0.83% -> 1.0253374 | J22: =G22+H22+I22 -> 164.55996 | L22: =J22-K22 -> 164.55996
A23: 17 | B23: SAM SOMONY | C23: M | D23: MEMBER | E23: 45171 | F23: NOP VY | G23: 392.00211 | H23: 425 | I23: =G23*0.83% -> 3.2536175 | J23: =G23+H23+I23 -> 820.25573 | L23: =J23-K23 -> 820.25573
A24: 18 | B24: KOY MAQUIS | C24: M | D24: MEMBER | E24: 45173 | F24: HONG REAKSMEY | G24: 66.728991 | H24: 20 | I24: =G24*0.83% -> 0.55385062 | J24: =G24+H24+I24 -> 87.282841 | L24: =J24-K24 -> 87.282841
A25: 19 | B25: LY MALIN | C25: F | D25: MEMBER | E25: 45171 | F25: OU RITHY | G25: 164.72596 | H25: 30 | I25: =G25*0.83% -> 1.3672255 | J25: =G25+H25+I25 -> 196.09319 | L25: =J25-K25 -> 196.09319
A26: 20 | B26: VAN BUNNA | C26: M | D26: MEMBER | E26: 45171 | F26: PECH PISEY | G26: 51.514139 | H26: 20 | I26: =G26*0.83% -> 0.42756735 | J26: =G26+H26+I26 -> 71.941706 | L26: =J26-K26 -> 71.941706
A27: 21 | B27: CHAN THEARA | C27: F | D27: MEMBER | E27: 45175 | F27: HONG REAKSMEY | G27: 5.2109732 | H27: 30 | I27: =G27*0.83% -> 0.043251078 | J27: =G27+H27+I27 -> 35.254224 | L27: =J27-K27 -> 35.254224
A28: 22 | B28: LONG BORIN | C28: F | D28: MEMBER | E28: 45140 | F28: NOP VY | G28: 107.78377 | I28: =G28*0.83% -> 0.89460526 | J28: =G28+H28+I28 -> 108.67837 | L28: =J28-K28 -> 108.67837
A29: 23 | B29: SOEUNG SAROEUN | C29: M | D29: MEMBER | E29: 45171 | F29: NOP VY | G29: 77.308463 | H29: 50 | I29: =G29*0.83% -> 0.64166024 | J29: =G29+H29+I29 -> 127.95012 | L29: =J29-K29 -> 127.95012
A30: 24 | B30: TUY SYTHIENG | C30: M | D30: MEMBER | E30: 45146 | F30: OU RITHY | G30: 202.08881 | I30: =G30*0.83% -> 1.6773371 | J30: =G30+H30+I30 -> 203.76614 | L30: =J30-K30 -> 203.76614
A31: 25 | B31: CHHEOUNG VEASNA | C31: M | D31: MEMBER | E31: 45174 | F31: SAM SOMONY | G31: 213.50741 | H31: 100 | I31: =G31*0.83% -> 1.7721115 | J31: =G31+H31+I31 -> 315.27952 | L31: =J31-K31 -> 315.27952
A32: 26 | B32: OM MANITH | C32: M | D32: MEMBER | E32: 45059 | F32: OU RITHY | G32: 20.502145 | I32: =G32*0.83% -> 0.1701678 | J32: =G32+H32+I32 -> 20.672313 | L32: =J32-K32 -> 20.672313
A33: 27 | B33: IM SOTHY | C33: M | D33: MEMBER | E33: 45060 | F33: PECH PISEY | G33: 30.753217 | I33: =G33*0.83% -> 0.2552517 | J33: =G33+H33+I33 -> 31.008469 | L33: =J33-K33 -> 31.008469
A34: 28 | B34: PA CHANROEUN | C34: M | D34: MEMBER | E34: 45085 | F34: NOP VY | G34: 201.66 | I34: =G34*0.83% -> 1.673778 | J34: =G34+H34+I34 -> 203.33378 | L34: =J34-K34 -> 203.33378
A35: 29 | B35: HENG SOCHEA | C35: F | D35: MEMBER | E35: 45171 | F35: OU RITHY | G35: 5 | J35: =G35+H35+I35 -> 5 | L35: =J35-K35 -> 5
A36: 30 | B36: TUM SOKRAKSA | C36: F | D36: MEMBER | E36: 45171 | F36: SIN PUTHEARY | G36: 50 | J36: =G36+H36+I36 -> 50 | L36: =J36-K36 -> 50
A37: 31 | B37: SDEUNG PHEARONG | D37: MEMBER | E37: 45173 | G37: 5 | J37: =G37+H37+I37 -> 5 | L37: =J37-K37 -> 5
G39: =SUM(G7:G37) -> 38711.023 | H39: =SUM(H7:H37) -> 1063.36 | I39: =SUM(I7:I37) -> 320.80349 | J39: =SUM(J7:J37) -> 40095.187 | K39: =SUM(K7:K37) -> 0 | L39: =SUM(L7:L37) -> 40095.187

Sheet Saving Monthly Oct-23
A1: SANSAM SAVING GROUP
A2: SAVING FROM 5USD PER MONTH BY GETTING INTEREST 10% PER YEAR
A3: SAVING DEPOSIT FROM 1ST - 10TH EVERY MONTH
A4: ACCESSIBLE LOAN ON 15TH EACH MONTH
A5: SAVING IN OCTOBER 2023
A6: NO | B6: NAME | C6: SEX | D6: ROLE | E6: SAVING DATE | F6: TEAM LEADER | G6: CAPITAL | H6: SAVING | I6: INTEREST | J6: BALANCE | K6: WITHDRAWAL | L6: TOTAL
A7: 1 | B7: ART THORN | C7: M | D7: FOUNDER | E7: 45149 | G7: 4057.298 | I7: =G7*0.83% -> 33.675574 | J7: =G7+H7+I7 -> 4090.9736 | L7: =J7-K7 -> 4090.9736
A8: 2 | B8: PECH PISEY | C8: M | D8: FOUNDER | E8: 45209 | G8: 6392.2493 | H8: 20 | I8: =G8*0.83% -> 53.055669 | J8: =G8+H8+I8 -> 6465.305 | L8: =J8-K8 -> 6465.305
A9: 3 | B9: HONG REAKSMEY | C9: M | D9: FOUNDER | E9: 45208 | G9: 6159.3718 | H9: 50 | I9: =G9*0.83% -> 51.122786 | J9: =G9+H9+I9 -> 6260.4946 | L9: =J9-K9 -> 6260.4946
A10: 4 | B10: SIN PUTHEARY | C10: F | D10: FOUNDER | E10: 45171 | G10: 5624.5188 | I10: =G10*0.83% -> 46.683506 | J10: =G10+H10+I10 -> 5671.2023 | L10: =J10-K10 -> 5671.2023
A11: 5 | B11: PAO VORN | C11: M | D11: FOUNDER | E11: 45208 | G11: 353.08265 | H11: 50 | I11: =G11*0.83% -> 2.930586 | J11: =G11+H11+I11 -> 406.01323 | L11: =J11-K11 -> 406.01323
A12: 6 | B12: SOR MORA | C12: M | D12: FOUNDER | E12: 45181 | G12: 2370.1971 | I12: =G12*0.83% -> 19.672636 | J12: =G12+H12+I12 -> 2389.8698 | L12: =J12-K12 -> 2389.8698
A13: 7 | B13: NOP VY | C13: M | D13: FOUNDER | E13: 45179 | G13: 6094.4764 | H13: 37.32 | I13: =G13*0.83% -> 50.584154 | J13: =G13+H13+I13 -> 6182.3805 | L13: =J13-K13 -> 6182.3805
A14: 8 | B14: OU RITHTY | C14: M | D14: FOUNDER | E14: 45201 | G14: 5612.0246 | H14: 50 | I14: =G14*0.83% -> 46.579804 | J14: =G14+H14+I14 -> 5708.6044 | L14: =J14-K14 -> 5708.6044
A15: 9 | B15: SENG RITHY | C15: M | D15: MEMBER | E15: 45201 | F15: NOP VY | G15: 41.181491 | H15: 5 | I15: =G15*0.83% -> 0.34180637 | J15: =G15+H15+I15 -> 46.523297 | L15: =J15-K15 -> 46.523297
A16: 10 | B16: OU TEP PHALLIN | C16: F | D16: MEMBER | E16: 45203 | F16: OU RITHY | G16: 123.54869 | H16: 20 | I16: =G16*0.83% -> 1.0254541 | J16: =G16+H16+I16 -> 144.57415 | L16: =J16-K16 -> 144.57415
A17: 11 | B17: YIM BUNTHENG | C17: M | D17: MEMBER | E17: 45201 | F17: HONG REAKSMEY | G17: 51.604879 | H17: 10 | I17: =G17*0.83% -> 0.42832049 | J17: =G17+H17+I17 -> 62.033199 | L17: =J17-K17 -> 62.033199
A18: 12 | B18: THENG SAVOEUN | C18: M | D18: MEMBER | E18: 45029 | F18: NOP VY | G18: 79.03321 | I18: =G18*0.83% -> 0.65597564 | J18: =G18+H18+I18 -> 79.689185 | L18: =J18-K18 -> 79.689185
A19: 13 | B19: UL VANN | C19: M | D19: MEMBER | E19: 45209 | F19: NOP VY | G19: 102.19286 | H19: 20 | I19: =G19*0.83% -> 0.84820074 | J19: =G19+H19+I19 -> 123.04106 | L19: =J19-K19 -> 123.04106
A20: 14 | B20: SIYONN SOTHEARITH | C20: M | D20: MEMBER | E20: 45079 | F20: HONG REAKSMEY | G20: 521.13292 | I20: =G20*0.83% -> 4.3254033 | J20: =G20+H20+I20 -> 525.45833 | L20: =J20-K20 -> 525.45833
A21: 15 | B21: YEAN REAKSMEY | C21: M | D21: MEMBER | E21: 45201 | F21: PECH PISEY | G21: 67.197664 | H21: 25 | I21: =G21*0.83% -> 0.55774061 | J21: =G21+H21+I21 -> 92.755405 | L21: =J21-K21 -> 92.755405
A22: 16 | B22: SON PENH | C22: M | D22: MEMBER | E22: 45170 | F22: PECH PISEY | G22: 164.55996 | I22: =G22*0.83% -> 1.3658477 | J22: =G22+H22+I22 -> 165.92581 | L22: =J22-K22 -> 165.92581
A23: 17 | B23: SAM SOMONY | C23: M | D23: MEMBER | E23: 45205 | F23: NOP VY | G23: 820.25573 | H23: 25 | I23: =G23*0.83% -> 6.8081225 | J23: =G23+H23+I23 -> 852.06385 | L23: =J23-K23 -> 852.06385
A24: 18 | B24: KOY MAQUIS | C24: M | D24: MEMBER | E24: 45201 | F24: HONG REAKSMEY | G24: 87.282841 | H24: 20 | I24: =G24*0.83% -> 0.72444758 | J24: =G24+H24+I24 -> 108.00729 | L24: =J24-K24 -> 108.00729
A25: 19 | B25: LY MALIN | C25: F | D25: MEMBER | E25: 45201 | F25: OU RITHY | G25: 196.09319 | H25: 30 | I25: =G25*0.83% -> 1.6275735 | J25: =G25+H25+I25 -> 227.72076 | L25: =J25-K25 -> 227.72076
A26: 20 | B26: VAN BUNNA | C26: M | D26: MEMBER | E26: 45171 | F26: PECH PISEY | G26: 71.941706 | H26: 5 | I26: =G26*0.83% -> 0.59711616 | J26: =G26+H26+I26 -> 77.538823 | L26: =J26-K26 -> 77.538823
A27: 21 | B27: CHAN THEARA | C27: F | D27: MEMBER | E27: 45211 | F27: HONG REAKSMEY | G27: 35.254224 | H27: 5 | I27: =G27*0.83% -> 0.29261006 | J27: =G27+H27+I27 -> 40.546834 | L27: =J27-K27 -> 40.546834
A28: 22 | B28: LONG BORIN | C28: F | D28: MEMBER | E28: 45140 | F28: NOP VY | G28: 108.67837 | I28: =G28*0.83% -> 0.90203048 | J28: =G28+H28+I28 -> 109.5804 | L28: =J28-K28 -> 109.5804
A29: 23 | B29: SOEUNG SAROEUN | C29: M | D29: MEMBER | E29: 45171 | F29: NOP VY | G29: 127.95012 | I29: =G29*0.83% -> 1.061986 | J29: =G29+H29+I29 -> 129.01211 | L29: =J29-K29 -> 129.01211
A30: 24 | B30: TUY SYTHIENG | C30: M | D30: MEMBER | E30: 45209 | F30: OU RITHY | G30: 203.76614 | H30: 100 | I30: =G30*0.83% -> 1.691259 | J30: =G30+H30+I30 -> 305.4574 | L30: =J30-K30 -> 305.4574
A31: 25 | B31: CHHEOUNG VEASNA | C31: M | D31: MEMBER | E31: 45201 | F31: SAM SOMONY | G31: 315.27952 | H31: 100 | I31: =G31*0.83% -> 2.6168201 | J31: =G31+H31+I31 -> 417.89634 | L31: =J31-K31 -> 417.89634
A32: 26 | B32: OM MANITH | C32: M | D32: MEMBER | E32: 45059 | F32: OU RITHY | G32: 20.672313 | I32: =G32*0.83% -> 0.17158019 | J32: =G32+H32+I32 -> 20.843893 | L32: =J32-K32 -> 20.843893
A33: 27 | B33: IM SOTHY | C33: M | D33: MEMBER | E33: 45209 | F33: PECH PISEY | G33: 31.008469 | H33: 30 | I33: =G33*0.83% -> 0.25737029 | J33: =G33+H33+I33 -> 61.265839 | L33: =J33-K33 -> 61.265839
A34: 28 | B34: PA CHANROEUN | C34: M | D34: MEMBER | E34: 45085 | F34: NOP VY | G34: 203.33378 | I34: =G34*0.83% -> 1.6876704 | J34: =G34+H34+I34 -> 205.02145 | L34: =J34-K34 -> 205.02145
A35: 29 | B35: HENG SOCHEA | C35: F | D35: MEMBER | E35: 45201 | F35: OU RITHY | G35: 5 | H35: 10 | I35: =G35*0.83% -> 0.0415 | J35: =G35+H35+I35 -> 15.0415 | L35: =J35-K35 -> 15.0415
A36: 30 | B36: TUM SOKRAKSA | C36: F | D36: MEMBER | E36: 45201 | F36: SIN PUTHEARY | G36: 50 | H36: 50 | I36: =G36*0.83% -> 0.415 | J36: =G36+H36+I36 -> 100.415 | L36: =J36-K36 -> 100.415
A37: 31 | B37: SDEUNG PHEARONG | D37: MEMBER | E37: 45173 | G37: 5 | I37: =G37*0.83% -> 0.0415 | J37: =G37+H37+I37 -> 5.0415 | L37: =J37-K37 -> 5.0415
A38: 32 | B38: TY SAMPHORS VICHEKA | D38: MEMBER | E38: 45201 | G38: 15 | J38: =G38+H38+I38 -> 15 | L38: =J38-K38 -> 15
A39: 33 | B39: CHUM CHANDARIN | D39: MEMBER | E39: 45201 | G39: 100 | J39: =G39+H39+I39 -> 100 | L39: =J39-K39 -> 100
A40: 34 | B40: PEANH KOEUN | D40: MEMBER | E40: 45201 | G40: 10 | J40: =G40+H40+I40 -> 10 | L40: =J40-K40 -> 10
...

Sheet Saving Monthly Nov-23
A1: SANSAM SAVING GROUP
A2: SAVING FROM 5USD PER MONTH BY GETTING INTEREST 10% PER YEAR
A3: SAVING DEPOSIT FROM 1ST - 10TH EVERY MONTH
A4: ACCESSIBLE LOAN ON 15TH EACH MONTH
A5: SAVING IN NOVEMBER 2023
